Workbook

Sheet 2024
B1: Auto Raya Sdn Bhd
B2: Monthly Summary After Sales 2024
C4: HINO
C5: ACCIDENT | H5: WINDSCREEN | M5: OTHERS | P5: TOTAL
C6: INTAKE | D6: INS - PARTS | E6: INS - LABOURS | F6: CREDIT | G6: CASH | H6: INTAKE | I6: INS - PARTS | J6: INS - LABOURS | K6: CREDIT | L6: CASH | M6: INTAKE | N6: CASH | O6: CREDIT | P6: INTAKE | Q6: TOTAL | R6: Avg
B7: JANUARY | C7: 2 | D7: ='HINO 2024'!G2+'HINO 2024'!G3 -> 54765.59 | E7: ='HINO 2024'!H2+'HINO 2024'!H3 -> 21180 | F7: 6366.9 | G7: 0 | H7: 1 | I7: ='HINO 2024'!G4 -> 696.06 | J7: ='HINO 2024'!H4 -> 420 | L7: 0 | M7: 0 | N7: 0 | O7: 0 | P7: =SUM(C7+H7+M7) -> 3 | Q7: =SUM(D7+E7+F7+G7+I7+J7+K7+L7+N7+O7) -> 83428.55 | R7: =Q7/P7 -> 27809.517
B8: FEBRUARY | C8: 1 | D8: ='HINO 2024'!G5 -> 53446.25 | E8: ='HINO 2024'!H5 -> 6000 | F8: 0 | G8: 0 | H8: 1 | I8: ='HINO 2024'!G6 -> 506.06 | J8: ='HINO 2024'!H6 -> 420 | L8: 0 | M8: 0 | N8: 0 | O8: 0 | P8: =SUM(C8+H8+M8) -> 2 | Q8: =SUM(D8+E8+F8+G8+I8+J8+K8+L8+N8+O8) -> 60372.31 | R8: =Q8/P8 -> 30186.155
B9: MARCH | C9: 0 | D9: 0 | E9: 0 | F9: 0 | G9: 0 | H9: 1 | I9: ='HINO 2024'!G7 -> 688.08 | J9: ='HINO 2024'!H7 -> 420 | L9: 0 | M9: 0 | N9: 0 | O9: 0 | P9: =SUM(C9+H9+M9) -> 1 | Q9: =SUM(D9+E9+F9+G9+I9+J9+K9+L9+N9+O9) -> 1108.08 | R9: =Q9/P9 -> 1108.08
B10: APRIL | C10: 2 | D10: ='HINO 2024'!G10+'HINO 2024'!G11 -> 15447.13 | E10: ='HINO 2024'!H10+'HINO 2024'!H11 -> 5616 | F10: 5700 | G10: 0 | H10: 2 | I10: ='HINO 2024'!G8+'HINO 2024'!G9 -> 1759.11 | J10: ='HINO 2024'!H8+'HINO 2024'!H9 -> 840 | L10: 0 | M10: 0 | N10: 0 | O10: 0 | P10: =SUM(C10+H10+M10) -> 4 | Q10: =SUM(D10+E10+F10+G10+I10+J10+K10+L10+N10+O10) -> 29362.24 | R10: =Q10/P10 -> 7340.56
B11: MAY | C11: 2 | D11: ='HINO 2024'!G12+'HINO 2024'!G15 -> 34184.35 | E11: ='HINO 2024'!H12+'HINO 2024'!H15 -> 6768 | F11: 912 | G11: 0 | H11: 3 | I11: ='HINO 2024'!G13+'HINO 2024'!G14+'HINO 2024'!G16 -> 1585.56 | J11: ='HINO 2024'!H13+'HINO 2024'!H14+'HINO 2024'!H16 -> 1440 | L11: 0 | M11: 0 | N11: 0 | O11: 0 | P11: =SUM(C11+H11+M11) -> 5 | Q11: =SUM(D11+E11+F11+G11+I11+J11+K11+L11+N11+O11) -> 44889.91 | R11: =Q11/P11 -> 8977.982
B12: JUNE | C12: 4 | D12: ='HINO 2024'!G17+'HINO 2024'!G18+'HINO 2024'!G19+'HINO 2024'!G21 -> 89981.07 | E12: ='HINO 2024'!H17+'HINO 2024'!H18+'HINO 2024'!H19+'HINO 2024'!H21 -> 17820 | F12: 11400 | G12: 0 | H12: 1 | I12: ='HINO 2024'!G20 -> 973.08 | J12: ='HINO 2024'!H20 -> 420 | L12: 0 | M12: 0 | N12: 0 | O12: 0 | P12: =SUM(C12+H12+M12) -> 5 | Q12: =SUM(D12+E12+F12+G12+I12+J12+K12+L12+N12+O12) -> 120594.15 | R12: =Q12/P12 -> 24118.83
B13: JULY | C13: 4 | D13: ='HINO 2024'!G30+'HINO 2024'!G31+'HINO 2024'!G34+'HINO 2024'!G37 -> 101460.05 | E13: ='HINO 2024'!H30+'HINO 2024'!H31+'HINO 2024'!H34+'HINO 2024'!H37 -> 24948 | F13: 237.5 | G13: 0 | H13: 0 | I13: 0 | J13: 0 | L13: 0 | M13: 2 | N13: 3350 | P13: =SUM(C13+H13+M13) -> 6 | Q13: =SUM(D13+E13+F13+G13+I13+J13+K13+L13+N13+O13) -> 129995.55 | R13: =Q13/P13 -> 21665.925
B14: AUGUST | C14: 2 | D14: ='HINO 2024'!G38+'HINO 2024'!G39 -> 51943.8 | E14: ='HINO 2024'!H38+'HINO 2024'!H39 -> 11412 | F14: 11670 | G14: 0 | H14: 0 | I14: 0 | J14: 0 | L14: 0 | M14: 0 | N14: 0 | O14: 0 | P14: =SUM(C14+H14+M14) -> 2 | Q14: =SUM(D14+E14+F14+G14+I14+J14+K14+L14+N14+O14) -> 75025.8 | R14: =Q14/P14 -> 37512.9
B15: SEPTEMBER | C15: 4 | D15: ='HINO 2024'!G40+'HINO 2024'!G41+'HINO 2024'!G42+'HINO 2024'!G43 -> 67422.15 | E15: ='HINO 2024'!H40+'HINO 2024'!H41+'HINO 2024'!H42+'HINO 2024'!H43 -> 17688 | F15: 4562 | G15: 0 | H15: 0 | I15: 0 | J15: 0 | L15: 0 | M15: 0 | N15: 0 | O15: 0 | P15: =SUM(C15+H15+M15) -> 4 | Q15: =SUM(D15+E15+F15+G15+I15+J15+K15+L15+N15+O15) -> 89672.15 | R15: =Q15/P15 -> 22418.037
B16: OCTOBER | C16: 1 | D16: ='HINO 2024'!G45 -> 6402.5 | E16: ='HINO 2024'!H45 -> 4380 | F16: 3277.5 | G16: 0 | H16: 1 | I16: ='HINO 2024'!G44 -> 973.08 | J16: ='HINO 2024'!H44 -> 420 | L16: 0 | M16: 0 | N16: 0 | O16: 0 | P16: =SUM(C16+H16+M16) -> 2 | Q16: =SUM(D16+E16+F16+G16+I16+J16+K16+L16+N16+O16) -> 15453.08 | R16: =Q16/P16 -> 7726.54
B17: NOVEMBER | C17: 2 | D17: ='HINO 2024'!G46+'HINO 2024'!G47 -> 82952.85 | E17: ='HINO 2024'!H46+'HINO 2024'!H47 -> 10620 | F17: 8521.26 | G17: 0 | H17: 0 | I17: 0 | J17: 0 | L17: 0 | M17: 0 | N17: 0 | O17: 0 | P17: =SUM(C17+H17+M17) -> 2 | Q17: =SUM(D17+E17+F17+G17+I17+J17+K17+L17+N17+O17) -> 102094.11 | R17: =Q17/P17 -> 51047.055
B18: DECEMBER | C18: 1 | D18: ='HINO 2024'!G57 -> 1045.01 | E18: ='HINO 2024'!H57 -> 262.2 | F18: 2090 | G18: 0 | H18: 1 | I18: ='HINO 2024'!G56 -> 973.08 | J18: ='HINO 2024'!H56 -> 420 | L18: 0 | M18: 0 | N18: 0 | O18: 0 | P18: =SUM(C18+H18+M18) -> 2 | Q18: =SUM(D18+E18+F18+G18+I18+J18+K18+L18+N18+O18) -> 4790.29 | R18: =Q18/P18 -> 2395.145
C19: =SUM(C7:C18) -> 25 | D19: =SUM(D7:D18) -> 559050.75 | E19: =SUM(E7:E18) -> 126694.2 | F19: =SUM(F7:F18) -> 54737.16 | G19: =SUM(G7:G18) -> 0 | H19: =SUM(H7:H18) -> 11 | I19: =SUM(I7:I18) -> 8154.11 | J19: =SUM(J7:J18) -> 4800 | ... Q19: =SUM(Q7:Q18) -> 756786.22 | R19: =Q19/P19 -> 19915.427
C22: MITSUBISHI
C23: ACCIDENT | H23: WINDSCREEN | M23: OTHERS | P23: TOTAL
C24: INTAKE | D24: INS - PARTS | E24: INS - LABOURS | F24: CREDIT | G24: CASH | H24: INTAKE | I24: INS - PARTS | J24: INS - LABOURS | K24: CREDIT | L24: CASH | M24: INTAKE | N24: CASH | O24: CREDIT | P24: INTAKE | Q24: TOTAL | R24: Avg
B25: JANUARY | C25: 7 | D25: ='MITS 2024'!G2+'MITS 2024'!G3+'MITS 2024'!G6+'MITS 2024'!G7+'MITS 2024'!G8+'MITS 2024'!G9+'MITS 2024'!G14 -> 93567.1 | E25: ='MITS 2024'!H2+'MITS 2024'!H3+'MITS 2024'!H6+'MITS 2024'!H7+'MITS 2024'!H8+'MITS 2024'!H9+'MITS 2024'!H14 -> 30384 | G25: 0 | H25: 5 | I25: ='MITS 2024'!G4+'MITS 2024'!G11+'MITS 2024'!G12+'MITS 2024'!G13+'MITS 2024'!G15 -> 9659.41 | J25: ='MITS 2024'!H4+'MITS 2024'!H11+'MITS 2024'!H12+'MITS 2024'!H13+'MITS 2024'!H15 -> 1248 | K25: 0 | L25: 0 | M25: 1 | N25: 1400 | O25: 0 | P25: =SUM(C25+H25+M25) -> 13 | Q25: =SUM(D25+E25+F25+G25+I25+J25+K25+L25+N25+O25) -> 136258.51 | R25: =Q25/P25 -> 10481.424
B26: FEBRUARY | C26: 2 | D26: ='MITS 2024'!G16+'MITS 2024'!G18 -> 52204.13 | E26: ='MITS 2024'!H16+'MITS 2024'!H18 -> 7488 | G26: 0 | H26: 1 | I26: ='MITS 2024'!G19 -> 2237.22 | J26: ='MITS 2024'!H19 -> 240 | K26: 0 | L26: 0 | M26: 1 | N26: 0 | O26: 10870.95 | P26: =SUM(C26+H26+M26) -> 4 | Q26: =SUM(D26+E26+F26+G26+I26+J26+K26+L26+N26+O26) -> 73040.3 | R26: =Q26/P26 -> 18260.075
B27: MARCH | C27: 7 | D27: ='MITS 2024'!G22+'MITS 2024'!G24+'MITS 2024'!G26+'MITS 2024'!G28+'MITS 2024'!G29+'MITS 2024'!G30+'MITS 2024'!G31 -> 82354.95 | E27: ='MITS 2024'!H22+'MITS 2024'!H24+'MITS 2024'!H26+'MITS 2024'!H28+'MITS 2024'!H29+'MITS 2024'!H30+'MITS 2024'!H31 -> 23040 | F27: 8699.63 | G27: 0 | H27: 4 | I27: ='MITS 2024'!G25+'MITS 2024'!G27+'MITS 2024'!G34 -> 6231.13 | J27: ='MITS 2024'!H25+'MITS 2024'!H27+'MITS 2024'!H34 -> 1266 | K27: 0 | L27: 2131.1 | M27: 2 | N27: 1344.1 | P27: =SUM(C27+H27+M27) -> 13 | Q27: =SUM(D27+E27+F27+G27+I27+J27+K27+L27+N27+O27) -> 125066.91 | R27: =Q27/P27 -> 9620.5315
B28: APRIL | C28: 7 | D28: ='MITS 2024'!G37+'MITS 2024'!G38+'MITS 2024'!G39+'MITS 2024'!G40+'MITS 2024'!G41+'MITS 2024'!G47+'MITS 2024'!G52 -> 82116.35 | E28: ='MITS 2024'!H37+'MITS 2024'!H38+'MITS 2024'!H39+'MITS 2024'!H40+'MITS 2024'!H41+'MITS 2024'!H47+'MITS 2024'!H52 -> 22728 | F28: 10184.71 | G28: 0 | H28: 6 | I28: ='MITS 2024'!G35+'MITS 2024'!G36+'MITS 2024'!G42+'MITS 2024'!G43+'MITS 2024'!G44+'MITS 2024'!G46 -> 11876.13 | J28: ='MITS 2024'!H35+'MITS 2024'!H36+'MITS 2024'!H42+'MITS 2024'!H43+'MITS 2024'!H44+'MITS 2024'!H46 -> 1428 | K28: 0 | L28: 0 | M28: 4 | N28: 0 | O28: 1130 | P28: =SUM(C28+H28+M28) -> 17 | Q28: =SUM(D28+E28+F28+G28+I28+J28+K28+L28+N28+O28) -> 129463.19 | R28: =Q28/P28 -> 7615.4818
B29: MAY | C29: 10 | D29: ='MITS 2024'!G53+'MITS 2024'!G54+'MITS 2024'!G55+'MITS 2024'!G56+'MITS 2024'!G61+'MITS 2024'!G63+'MITS 2024'!G64+'MITS 2024'!G65+'MITS 2024'!G66+'MITS 2024'!G69 -> 83909.6 | E29: ='MITS 2024'!H53+'MITS 2024'!H54+'MITS 2024'!H55+'MITS 2024'!H56+'MITS 2024'!H61+'MITS 2024'!H63+'MITS 2024'!H64+'MITS 2024'!H65+'MITS 2024'!H66+'MITS 2024'!H69 -> 26700 | F29: 712.5 | G29: 0 | H29: 3 | I29: ='MITS 2024'!G67+'MITS 2024'!G68+'MITS 2024'!G70 -> 4617.89 | J29: ='MITS 2024'!H67+'MITS 2024'!H68+'MITS 2024'!H70 -> 720 | K29: 0 | L29: 0 | M29: 6 | N29: 0 | O29: 2705.85 | P29: =SUM(C29+H29+M29) -> 19 | Q29: =SUM(D29+E29+F29+G29+I29+J29+K29+L29+N29+O29) -> 119365.84 | R29: =Q29/P29 -> 6282.4126
B30: JUNE | C30: 5 | D30: ='MITS 2024'!G72+'MITS 2024'!G73+'MITS 2024'!G74+'MITS 2024'!G81+'MITS 2024'!G82 -> 66073.51 | E30: ='MITS 2024'!H72+'MITS 2024'!H73+'MITS 2024'!H74+'MITS 2024'!H81+'MITS 2024'!H82 -> 18072 | F30: 0 | G30: 1528.86 | H30: 5 | I30: ='MITS 2024'!G75+'MITS 2024'!G76+'MITS 2024'!G77+'MITS 2024'!G78+'MITS 2024'!G79 -> 8742.65 | J30: ='MITS 2024'!H75+'MITS 2024'!H76+'MITS 2024'!H77+'MITS 2024'!H78+'MITS 2024'!H79 -> 1164 | K30: 0 | L30: 0 | M30: 0 | N30: 0 | O30: 0 | P30: =SUM(C30+H30+M30) -> 10 | Q30: =SUM(D30+E30+F30+G30+I30+J30+K30+L30+N30+O30) -> 95581.02 | R30: =Q30/P30 -> 9558.102
B31: JULY | C31: 9 | D31: ='MITS 2024'!G83+'MITS 2024'!G84+'MITS 2024'!G85+'MITS 2024'!G86+'MITS 2024'!G87+'MITS 2024'!G89+'MITS 2024'!G91+'MITS 2024'!G93+'MITS 2024'!G95 -> 162237.65 | E31: ='MITS 2024'!H83+'MITS 2024'!H84+'MITS 2024'!H85+'MITS 2024'!H86+'MITS 2024'!H87+'MITS 2024'!H89+'MITS 2024'!H91+'MITS 2024'!H93+'MITS 2024'!H95 -> 41439 | F31: 6368.37 | G31: 0 | H31: 5 | I31: ='MITS 2024'!G88+'MITS 2024'!G90+'MITS 2024'!G92+'MITS 2024'!G94+'MITS 2024'!G96 -> 6771.83 | J31: ='MITS 2024'!H88+'MITS 2024'!H90+'MITS 2024'!H92+'MITS 2024'!H94+'MITS 2024'!H96 -> 912 | K31: 0 | L31: 0 | M31: 0 | N31: 0 | O31: 0 | P31: =SUM(C31+H31+M31) -> 14 | Q31: =SUM(D31+E31+F31+G31+I31+J31+K31+L31+N31+O31) -> 217728.85 | R31: =Q31/P31 -> 15552.061
B32: AUGUST | C32: 10 | D32: ='MITS 2024'!G100+'MITS 2024'!G101+'MITS 2024'!G102+'MITS 2024'!G103+'MITS 2024'!G106+'MITS 2024'!G107+'MITS 2024'!G108+'MITS 2024'!G111+'MITS 2024'!G112+'MITS 2024'!G113 -> 72365.72 | E32: ='MITS 2024'!H100+'MITS 2024'!H101+'MITS 2024'!H102+'MITS 2024'!H103+'MITS 2024'!H106+'MITS 2024'!H107+'MITS 2024'!H108+'MITS 2024'!H111+'MITS 2024'!H112+'MITS 2024'!H113 -> 33528 | F32: 5076.27 | G32: 0 | H32: 3 | I32: ='MITS 2024'!G104+'MITS 2024'!G109+'MITS 2024'!G110 -> 7186.78 | J32: ='MITS 2024'!H104+'MITS 2024'!H109+'MITS 2024'!H110 -> 792 | K32: 0 | L32: 0 | M32: 4 | N32: 300 | O32: 6811.39 | P32: =SUM(C32+H32+M32) -> 17 | Q32: =SUM(D32+E32+F32+G32+I32+J32+K32+L32+N32+O32) -> 126060.16 | R32: =Q32/P32 -> 7415.3035
B33: SEPTEMBER | C33: 5 | D33: ='MITS 2024'!G114+'MITS 2024'!G119+'MITS 2024'!G121+'MITS 2024'!G122+'MITS 2024'!G123 -> 56523.05 | E33: ='MITS 2024'!H114+'MITS 2024'!H119+'MITS 2024'!H121+'MITS 2024'!H122+'MITS 2024'!H123 -> 24036 | F33: 0 | G33: 0 | H33: 5 | I33: ='MITS 2024'!G118+'MITS 2024'!G120+'MITS 2024'!G125+'MITS 2024'!G126+'MITS 2024'!G127 -> 10975.58 | J33: ='MITS 2024'!H118+'MITS 2024'!H120+'MITS 2024'!H125+'MITS 2024'!H126+'MITS 2024'!H127 -> 1320 | K33: 0 | L33: 0 | M33: 4 | N33: 2102.1 | O33: 930 | P33: =SUM(C33+H33+M33) -> 14 | Q33: =SUM(D33+E33+F33+G33+I33+J33+K33+L33+N33+O33) -> 95886.73 | R33: =Q33/P33 -> 6849.0521
B34: OCTOBER | C34: 8 | D34: ='MITS 2024'!G128+'MITS 2024'!G129+'MITS 2024'!G131+'MITS 2024'!G133+'MITS 2024'!G134+'MITS 2024'!G136+'MITS 2024'!G137+'MITS 2024'!G138 -> 166938.41 | E34: ='MITS 2024'!H128+'MITS 2024'!H129+'MITS 2024'!H131+'MITS 2024'!H133+'MITS 2024'!H134+'MITS 2024'!H136+'MITS 2024'!H137+'MITS 2024'!H138 -> 28158 | F34: 2907 | G34: 0 | H34: 7 | I34: ='MITS 2024'!G130+'MITS 2024'!G135+'MITS 2024'!G139+'MITS 2024'!G140+'MITS 2024'!G141+'MITS 2024'!G142+'MITS 2024'!G145 -> 14217.34 | J34: ='MITS 2024'!H130+'MITS 2024'!H135+'MITS 2024'!H139+'MITS 2024'!H140+'MITS 2024'!H141+'MITS 2024'!H142+'MITS 2024'!H145 -> 1860 | K34: 0 | L34: 0 | M34: 3 | N34: 7884.81 | O34: 1961 | P34: =SUM(C34+H34+M34) -> 18 | Q34: =SUM(D34+E34+F34+G34+I34+J34+K34+L34+N34+O34) -> 223926.56 | R34: =Q34/P34 -> 12440.364
B35: NOVEMBER | C35: 9 | D35: ='MITS 2024'!G146+'MITS 2024'!G147+'MITS 2024'!G148+'MITS 2024'!G149+'MITS 2024'!G150+'MITS 2024'!G151+'MITS 2024'!G156+'MITS 2024'!G157+'MITS 2024'!G158 -> 68433.45 | E35: ='MITS 2024'!H146+'MITS 2024'!H147+'MITS 2024'!H148+'MITS 2024'!H149+'MITS 2024'!H150+'MITS 2024'!H151+'MITS 2024'!H156+'MITS 2024'!H157+'MITS 2024'!H158 -> 17389 | F35: 4421.28 | G35: 0 | H35: 4 | I35: ='MITS 2024'!G152+'MITS 2024'!G153+'MITS 2024'!G154+'MITS 2024'!G155 -> 8353.54 | J35: ='MITS 2024'!H152+'MITS 2024'!H153+'MITS 2024'!H154+'MITS 2024'!H155 -> 1032 | K35: 0 | L35: 0 | M35: 0 | N35: 0 | O35: 0 | P35: =SUM(C35+H35+M35) -> 13 | Q35: =SUM(D35+E35+F35+G35+I35+J35+K35+L35+N35+O35) -> 99629.27 | R35: =Q35/P35 -> 7663.79
B36: DECEMBER | C36: 2 | D36: ='MITS 2024'!G159+'MITS 2024'!G160 -> 59314.97 | E36: ='MITS 2024'!H159+'MITS 2024'!H160 -> 7476 | F36: 1320.5 | G36: 0 | H36: 7 | I36: ='MITS 2024'!G161+'MITS 2024'!G162+'MITS 2024'!G163+'MITS 2024'!G164+'MITS 2024'!G165+'MITS 2024'!G166+'MITS 2024'!G167 -> 11923.41 | J36: ='MITS 2024'!H161+'MITS 2024'!H162+'MITS 2024'!H163+'MITS 2024'!H164+'MITS 2024'!H165+'MITS 2024'!H166+'MITS 2024'!H167 -> 1776 | K36: 951.48 | L36: 0 | M36: 0 | N36: 0 | O36: 0 | P36: =SUM(C36+H36+M36) -> 9 | Q36: =SUM(D36+E36+F36+G36+I36+J36+K36+L36+N36+O36) -> 82762.36 | R36: =Q36/P36 -> 9195.8178
C37: =SUM(C25:C36) -> 81 | D37: =SUM(D25:D36) -> 1046038.9 | E37: =SUM(E25:E36) -> 280438 | F37: =SUM(F25:F36) -> 39690.26 | G37: =SUM(G25:G36) -> 1528.86 | H37: =SUM(H25:H36) -> 55 | I37: =SUM(I25:I36) -> 102792.91 | J37: =SUM(J25:J36) -> 13758 | ... Q37: =SUM(Q25:Q36) -> 1524769.7 | R37: =Q37/P37 -> 9470.6193
C40: AFTER SALES SERVICE
C41: SERVICE FUSO | M41: SERVICE HINO | P41: TOTAL
C42: INTAKE | D42: FREE SERVICE | G42: INTAKE | H42: WARRANTY | I42: INTAKE | L42: CASH | M42: INTAKE | N42: INVOICE | O42: CASH | P42: INTAKE | Q42: TOTAL | R42: Avg
B43: JANUARY | C43: 1 | D43: 348.21 | G43: 0 | H43: 0 | I43: 2 | L43: 1448.67 | M43: 0 | N43: 0 | O43: 0 | P43: =SUM(C43+G43+I43+M43) -> 3 | Q43: =SUM(D43+H43+L43+N43) -> 1796.88 | R43: =Q43/P43 -> 598.96
B44: FEBRUARY | C44: 0 | D44: 0 | G44: 0 | H44: 0 | I44: 0 | L44: 0 | M44: 0 | N44: 0 | O44: 0 | P44: =SUM(C44+G44+I44+M44) -> 0 | Q44: =SUM(D44+H44+L44+N44) -> 0 | R44: =Q44/P44 -> #DIV/0!
B45: MARCH | C45: 3 | D45: 1426.8 | G45: 1 | H45: 205.68 | I45: 1 | L45: 1091 | M45: 0 | N45: 0 | O45: 0 | P45: =SUM(C45+G45+I45+M45) -> 5 | Q45: =SUM(D45+H45+L45+N45) -> 2723.48 | R45: =Q45/P45 -> 544.696
...

Sheet MITS 2023
A1: TRANSNO | C1: DATE | D1: CUSTOMER NAME | E1: REG NO | F1: JOBNO | G1: P.TOTAL | H1: L.TOTAL | I1: GTOTAL | J1: TOTAL | K1: SVC TYPE
A2: MBPCASH2311001 | B2: NOV | C2: 45239 | D2: NARIZAH | E2: VKJ1617 | F2: MBPWO2311001 | G2: 282 | H2: 318 | I2: 600 | J2: 600 | K2: CR | L2: SPRAY
A3: MBPSI2311001 | B3: NOV | C3: 45254 | D3: AUTO RAYA TIMUR SDN BHD | E3: VKM7660 | F3: MBPWO2311011 | G3: 1084.9 | H3: 228 | I3: 1312.9 | J3: 1312.9 | K3: WS
A4: MBPSI2312001 | B4: DEC | C4: 45262 | D4: MUHAMMAD FARIDDUDIN BIN SALLEH | E4: SMF9353 | F4: MBPWO2312007 | G4: 900 | I4: 900 | J4: 900 | K4: CR | L4: SPRAY
A5: MBPSI2312002 | B5: DEC | C5: 45273 | D5: AUTO RAYA TIMUR SDN BHD | E5: VFU9990 | F5: MBPWO2311008 | G5: 1517.35 | H5: 300 | I5: 1817.35 | J5: 1817.35 | K5: WS
A6: MBPSI2312003 | B6: DEC | C6: 45287 | D6: AUTO RAYA TIMUR SDN BHD | E6: VJN4429 | F6: MBPWO2311015 | G6: 1566.05 | H6: 276 | I6: 1842.05 | J6: 1842.05 | K6: WS
A7: MBPSI2312004 | B7: DEC | C7: 45287 | D7: AUTO RAYA TIMUR SDN BHD | E7: CEQ6122 | F7: MBPWO2311014 | G7: 2596.32 | H7: 240 | I7: 2836.32 | J7: 2836.32 | K7: WS
A8: MBPSI2312005 | B8: DEC | C8: 45288 | D8: AUTO RAYA TIMUR SDN BHD | E8: JUK1169 | F8: MBPWO2311012 | G8: 1642.39 | H8: 708 | I8: 2350.39 | J8: 2350.39 | K8: OD
A9: MBPSI2312006 | B9: DEC | C9: 45288 | D9: AUTO RAYA TIMUR SDN BHD | E9: VKH8524 | F9: MBPWO2311013 | G9: 3739.61 | H9: 3132 | I9: 6871.61 | J9: 6871.61 | K9: OD
A10: MBPSI2312007 | B10: DEC | C10: 45288 | D10: AUTO RAYA TIMUR SDN BHD | E10: SMF9353 | F10: MBPWO2311003 | G10: 19138.12 | H10: 3840 | I10: 22978.12 | J10: 22978.12 | K10: OD
A11: MBPSI2312008 | B11: DEC | C11: 45290 | D11: AUTO RAYA TIMUR SDN BHD | E11: VFW1566 | F11: MBPWO2311005 | G11: 31483.63 | H11: 2916 | I11: 34399.63 | J11: 34399.63 | K11: OD
A12: MBPSI2312009 | B12: DEC | C12: 45289 | D12: AUTO RAYA TIMUR SDN BHD | E12: BQQ2927 | F12: MBPWO2312002 | G12: 11115 | H12: 2736 | I12: 13851 | J12: 13851 | K12: OD
A13: MBPSI2312010 | B13: DEC | C13: 45290 | D13: AUTO RAYA TIMUR SDN BHD | E13: BQN1336 | F13: MBPWO2311006 | G13: 5586.6 | H13: 7908 | I13: 13494.6 | J13: 13494.6 | K13: OD
J15: =SUM(J2:J14) -> 103253.97
A21: TRANSNO | B21: MONTH | C21: DATE | D21: CUSTOMER NAME | E21: REFERENCE | F21: TOTAL
A22: MBPIV2403013 | B22: MAR | C22: 45365 | D22: AUTO RAYA TIMUR SDN BHD | E22: VJJ9120 | F22: 822.7 | G22: OD
A23: MBPIV2403014 | B23: MAR | C23: 45373 | D23: AUTO RAYA TIMUR SDN BHD | E23: AKT3446 | F23: 3126.93 | G23: OD
A24: MBPIV2403015 | B24: MAR | C24: 45376 | D24: AUTO RAYA TIMUR SDN BHD | E24: CEP8036 | F24: 4750 | G24: OD
F26: =SUM(F22:F24) -> 8699.63

Sheet MITS 2024
A1: TRANSNO | C1: DATE | D1: CUSTOMER NAME | E1: REG NO | F1: JOBNO | G1: P.TOTAL | H1: L.TOTAL | I1: GTOTAL | J1: TOTAL | K1: SVC TYPE
A2: MBPSI2401001 | B2: JAN | C2: 45295 | D2: AUTO RAYA TIMUR SDN BHD | E2: CEM8056 | F2: MBPWO2311007 | G2: 17559.82 | H2: 6072 | I2: 23631.82 | J2: 23631.82 | K2: OD
A3: MBPSI2401002 | C3: 45296 | D3: AUTO RAYA TIMUR SDN BHD | E3: CEN9684 | F3: MBPWO2401001 | G3: 5047.53 | H3: 2628 | I3: 7675.53 | J3: 7675.53 | K3: OD
A4: MBPSI2401003 | B4: JAN | C4: 45297 | D4: AUTO RAYA TIMUR SDN BHD | E4: KFN7175 | F4: MBPWO2312006 | G4: 2936.8 | H4: 240 | I4: 3176.8 | J4: 3176.8 | K4: WS
A5: MBPSI2401004 | C5: 45299 | D5: MUHAMAD KHAIRUL LUBIS BIN RAZAK | E5: KFP8082 | F5: MBPWO2401003 | G5: 90 | H5: 1310 | I5: 1400 | J5: 1400 | K5: CR | L5: CASH
A6: MBPSI2401005 | C6: 45301 | D6: AUTO RAYA TIMUR SDN BHD | E6: VKK5775 | F6: MBPWO2311009 | G6: 22110.19 | H6: 5328 | I6: 27438.19 | J6: 27438.19 | K6: OD
A7: MBPSI2401006 | C7: 45302 | D7: AUTO RAYA TIMUR SDN BHD | E7: VGY9225 | F7: MBPWO2312005 | G7: 5043.15 | H7: 1764 | I7: 6807.15 | J7: 6807.15 | K7: OD
A8: MBPSI2401007 | C8: 45308 | D8: AUTO RAYA TIMUR SDN BHD | E8: VHA8645 | F8: MBPWO2311004 | G8: 12185.29 | H8: 2616 | I8: 14801.29 | J8: 14801.29 | K8: OD
A9: MBPSI2401008 | C9: 45308 | D9: AUTO RAYA TIMUR SDN BHD | E9: SU7816G | F9: MBPWO2312004 | G9: 25105.62 | H9: 7956 | I9: 33061.62 | J9: 33061.62 | K9: OD
A10: MBPSI2401009 | C10: 45310 | D10: AUTO RAYA TIMUR SDN BHD | E10: WC4350F | F10: MBPWO2401007 | G10: 2025.57 | H10: 240 | I10: 0 | J10: 2265.57 | K10: CANCEL
A11: MBPSI2401010 | C11: 45317 | D11: AUTO RAYA TIMUR SDN BHD | E11: VHA8645 | F11: MBPWO2401006 | G11: 1646.32 | H11: 240 | I11: 1886.32 | J11: 1886.32 | K11: WS
A12: MBPSI2401011 | C12: 45317 | D12: AUTO RAYA TIMUR SDN BHD | E12: WC4350F | F12: MBPWO2401007 | G12: 1857.6 | H12: 240 | I12: 2097.6 | J12: 2097.6 | K12: WS
A13: MBPSI2401012 | C13: 45314 | D13: AUTO RAYA TIMUR SDN BHD | E13: JQW3320 | F13: MBPWO2401010 | G13: 1633.64 | H13: 252 | I13: 1885.64 | J13: 1885.64 | K13: WS
A14: MBPSI2401013 | C14: 45298 | D14: AUTO RAYA TIMUR SDN BHD | E14: VGL2124 | F14: MBPWO2401008 | G14: 6515.5 | H14: 4020 | I14: 10535.5 | J14: 10535.5 | K14: OD
A15: MBPSI2401014 | C15: 45317 | D15: AUTO RAYA TIMUR SDN BHD | E15: UMT221 | F15: MBPWO2401009 | G15: 1585.05 | H15: 276 | I15: 1861.05 | J15: 1861.05 | K15: WS
A16: MBPSI2402001 | B16: FEB | C16: 45327 | D16: AUTO RAYA TIMUR SDN BHD | E16: RAQ9297 | F16: MBPWO2311002 | G16: 37606.72 | H16: 4020 | I16: 41626.72 | J16: 41626.72 | K16: OD
A17: MBPSI2402002 | C17: 45327 | D17: AUTO RAYA TIMUR SDN BHD | E17: 31841 | F17: MBPWO2312003 | G17: 3951.75 | H17: 6919.2 | I17: 10870.95 | J17: 10870.95 | K17: CR | L17: CREDIT
A18: MBPSI2402003 | C18: 45342 | D18: AUTO RAYA TIMUR SDN BHD | E18: AKT3446 | F18: MBPWO2402001 | G18: 14597.41 | H18: 3468 | I18: 18065.41 | J18: 18065.41 | K18: OD
A19: MBPSI2402004 | B19: FEB | C19: 45345 | D19: AUTO RAYA TIMUR SDN BHD | E19: QAB1974G | F19: MBPWO2402006 | G19: 2237.22 | H19: 240 | I19: 2477.22 | J19: 2477.22 | K19: WS
A20: MBPSI2403001 | C20: 45352 | D20: MUHAMMAD FARIDDUDIN BIN SALLEH | E20: SMF9353 | F20: MBPWO2403003 | G20: 260 | I20: 260 | J20: 260 | K20: CR | L20: CASH
A21: MBPSI2403002 | C21: 45356 | D21: AUTO RAYA TIMUR SDN BHD | E21: TCF150 | F21: MBPWO2403005 | G21: 1340.5 | I21: 1340.5 | K21: TRAINING
A22: MBPSI2403003 | B22: MAR | C22: 45356 | D22: AUTO RAYA TIMUR SDN BHD | E22: VKU9306 | F22: MBPWO2402004 | G22: 12208.98 | H22: 3132 | I22: 15340.98 | J22: 15340.98 | K22: OD
A23: MBPSI2403004 | C23: 45356 | D23: AUTO RAYA TIMUR SDN BHD | E23: JUC1888 | F23: MBPWO2403006 | G23: 1129.5 | I23: 1129.5 | J23: 1129.5 | K23: TRAINING
A24: MBPSI2403005 | C24: 45356 | D24: AUTO RAYA TIMUR SDN BHD | E24: CET5945 | F24: MBPWO2402005 | G24: 10235.36 | H24: 2484 | I24: 12719.36 | J24: 12719.36 | K24: OD
A25: MBPSI2403006 | B25: MAR | C25: 45359 | D25: AUTO RAYA TIMUR SDN BHD | E25: CEH9366 | F25: MBPWO2403004 | G25: 1128.02 | H25: 276 | I25: 1404.02 | J25: 1404.02 | K25: WS
A26: MBPSI2403007 | C26: 45359 | D26: AUTO RAYA TIMUR SDN BHD | E26: VKU7912 | F26: MBPWO2401002 | G26: 3673.85 | H26: 2124 | I26: 5797.85 | J26: 5797.85 | K26: OD
A27: MBPSI2403008 | C27: 45360 | D27: AUTO RAYA TIMUR SDN BHD | E27: JDE5445 | F27: MBPWO2403002 | G27: 3021.35 | H27: 240 | I27: 3261.35 | J27: 3261.35 | K27: WS
A28: MBPSI2403009 | C28: 45365 | D28: AUTO RAYA TIMUR SDN BHD | E28: SMK6928 | F28: MBPWO2402010 | G28: 2755.2 | H28: 2124 | I28: 4879.2 | J28: 4879.2 | K28: OD
A29: MBPSI2403010 | C29: 45365 | D29: AUTO RAYA TIMUR SDN BHD | E29: VKU7912 | F29: MBPWO2401005 | G29: 24862.38 | H29: 4248 | I29: 29110.38 | J29: 29110.38 | K29: OD
A30: MBPSI2403011 | C30: 45365 | D30: AUTO RAYA TIMUR SDN BHD | E30: VJJ9120 | F30: MBPWO2402003 | G30: 15330.8 | H30: 4452 | I30: 19782.8 | J30: 19782.8 | K30: OD
A31: MBPSI2403012 | C31: 45369 | D31: AUTO RAYA TIMUR SDN BHD | E31: AMK4010 | F31: MBPWO2402002 | G31: 13288.38 | H31: 4476 | I31: 17764.38 | J31: 17764.38 | K31: OD
A32: MBPSI2403013 | C32: 45370 | D32: MOHD RUKMAN BIN ABU HASAN | E32: DET1782 | F32: MBPWO2403009 | G32: 808.08 | H32: 276 | I32: 1084.1 | J32: 1084.1 | K32: CR | L32: CASH | M32: SCREEN REPLACEMENT
A33: MBPSI2403014 | C33: 45378 | D33: SAIFUL AZHAR BIN IBRAHIM | E33: WWS7678 | F33: MBPWO2403011 | G33: 1879.12 | H33: 252 | I33: 2131.1 | J33: 2131.1 | K33: WS | L33: CASH
A34: MBPSI2403015 | C34: 45378 | D34: AUTO RAYA TIMUR SDN BHD | E34: DEQ7921 | F34: MBPWO2403008 | G34: 2081.76 | H34: 750 | I34: 2831.76 | J34: 2831.76 | K34: WS
A35: MBPSI2404001 | B35: APR | C35: 45386 | D35: AUTO RAYA TIMUR SDN BHD | E35: SU3892F | F35: MBPWO2403007 | G35: 2610.75 | H35: 240 | I35: 2850.75 | J35: 2850.75 | K35: WS
A36: MBPSI2404002 | C36: 45397 | D36: AUTO RAYA TIMUR SDN BHD | E36: CEM7985 | F36: MBPWO2403013 | G36: 2116.76 | H36: 240 | I36: 2356.76 | J36: 2356.76 | K36: WS
A37: MBPSI2404003 | B37: APR | C37: 45398 | D37: AUTO RAYA TIMUR SDN BHD | E37: WA4150C | F37: MBPWO2403001 | G37: 3079.1 | H37: 2448 | I37: 5527.1 | J37: 5527.1 | K37: OD
A38: MBPSI2404004 | C38: 45398 | D38: AUTO RAYA TIMUR SDN BHD | E38: KFQ7001 | F38: MBPWO2402011 | G38: 7758.89 | H38: 2148 | I38: 9906.89 | J38: 9906.89 | K38: OD
A39: MBPSI2404005 | C39: 45401 | D39: AUTO RAYA TIMUR SDN BHD | E39: BQQ2927 | F39: MBPWO2404001 | G39: 4897.85 | H39: 2172 | I39: 7069.85 | J39: 7069.85 | K39: OD
A40: MBPSI2404006 | C40: 45401 | D40: AUTO RAYA TIMUR SDN BHD | E40: CEP8036 | F40: MBPWO2312001 | G40: 38784.63 | H40: 5580 | I40: 44364.63 | J40: 44364.63 | K40: OD
...

Sheet HINO 2024
A1: TRANSNO | C1: DATE | D1: CUSTOMER NAME | E1: REG NO | F1: JOBNO | G1: P.TOTAL | H1: L.TOTAL | I1: GTOTAL | J1: DISC. | K1: TOTAL | L1: SVC TYPE | M1: SVC TYPE
A2: HBPSI2401001 | B2: JAN | C2: 45296 | D2: EDARAN RIZ SDN BHD | E2: VGS7608 | F2: HBPWO2311003 | G2: 24280.29 | H2: 13560 | I2: 37840.29 | K2: 37840.29 | L2: OD
A3: HBPSI2401002 | B3: JAN | C3: 45321 | D3: EDARAN RIZ SDN BHD | E3: VLB4149 | F3: HBPWO2312001 | G3: 30485.3 | H3: 7620 | I3: 38105.3 | K3: 38105.3 | L3: OD
A4: HBPSI2401003 | B4: JAN | C4: 45322 | D4: EDARAN RIZ SDN BHD | E4: CDF7298 | F4: HBPWO2401001 | G4: 696.06 | H4: 420 | I4: 1116.06 | K4: 1116.06 | L4: WS
A5: HBPSI2402001 | B5: FEB | C5: 45341 | D5: EDARAN RIZ SDN BHD | E5: BMN4706 | F5: HBPWO2311002 | G5: 53446.25 | H5: 6000 | I5: 59446.25 | K5: 59446.25 | L5: OD
A6: HBPSI2402002 | B6: FEB | C6: 45343 | D6: EDARAN RIZ SDN BHD | E6: CEA6128 | F6: HBPWO2402001 | G6: 506.06 | H6: 420 | I6: 926.06 | K6: 926.06 | L6: WS
A7: HBPSI2403001 | B7: MAR | C7: 45359 | D7: EDARAN RIZ SDN BHD | E7: KEM6686 | F7: HBPWO2403001 | G7: 688.08 | H7: 420 | I7: 1108.08 | K7: 1108.08 | L7: WS
A8: HBPSI2404001 | B8: APR | C8: 45383 | D8: EDARAN RIZ SDN BHD | E8: VHT4642 | F8: HBPWO2403005 | G8: 973.08 | H8: 420 | I8: 1393.08 | K8: 1393.08 | L8: WS
A9: HBPSI2404002 | B9: APR | C9: 45386 | D9: EDARAN RIZ SDN BHD | E9: SWE6668 | F9: HBPWO2403004 | G9: 786.03 | H9: 420 | I9: 1206.03 | K9: 1206.03 | L9: WS
A10: HBPSI2404003 | B10: APR | C10: 45399 | D10: EDARAN RIZ SDN BHD | E10: T/N2206 | F10: HBPWO2403002 | G10: 1390.48 | I10: 1390.48 | K10: 1390.48 | L10: OD
A11: HBPSI2404004 | B11: APR | C11: 45399 | D11: EDARAN RIZ SDN BHD | E11: CDJ7715 | F11: HBPWO2402002 | G11: 14056.65 | H11: 5616 | I11: 19672.65 | K11: 19672.65 | L11: OD
A12: HBPSI2405001 | B12: MAY | C12: 45418 | D12: EDARAN RIZ SDN BHD | E12: VHU1133 | F12: HBPWO2402003 | G12: 27624.85 | H12: 4008 | I12: 31632.85 | K12: 31632.85 | L12: OD
A13: HBPSI2405002 | B13: MAY | C13: 45422 | D13: EDARAN RIZ SDN BHD | E13: BKM5452 | F13: HBPWO2405001 | G13: 433.52 | H13: 480 | I13: 913.52 | K13: 913.52 | L13: WS
A14: HBPSI2405003 | B14: MAY | C14: 45422 | D14: EDARAN RIZ SDN BHD | E14: BKN3892 | F14: HBPWO2405002 | G14: 433.52 | H14: 480 | I14: 913.52 | K14: 913.52 | L14: WS
A15: HBPSI2405004 | B15: MAY | C15: 45433 | D15: EDARAN RIZ SDN BHD | E15: PPS6686 | F15: HBPWO2404004 | G15: 6559.5 | H15: 2760 | I15: 9319.5 | K15: 9319.5 | L15: OD
A16: HBPSI2405005 | B16: MAY | C16: 45442 | D16: EDARAN RIZ SDN BHD | E16: PNW3866 | F16: HBPWO2405007 | G16: 718.52 | H16: 480 | I16: 1198.52 | K16: 1198.52 | L16: WS
A17: HBPSI2406001 | B17: JUNE | C17: 45449 | D17: EDARAN RIZ SDN BHD | E17: CEQ8209 | F17: HBPWO2404003 | G17: 7073.27 | H17: 2280 | I17: 9353.27 | K17: 9353.27 | L17: OD
A18: HBPSI2406002 | B18: JUNE | C18: 45456 | D18: EDARAN RIZ SDN BHD | E18: MDP5398 | F18: HBPWO2404001 | G18: 22112.87 | H18: 3720 | I18: 25832.87 | K18: 25832.87 | L18: OD
A19: HBPSI2406003 | B19: JUNE | C19: 45458 | D19: EDARAN RIZ SDN BHD | E19: WA6461G | F19: HBPWO2405003 | G19: 5568.44 | H19: 3120 | I19: 8688.44 | K19: 8688.44 | L19: OD
A20: HBPSI2406004 | B20: JUNE | C20: 45461 | D20: EDARAN RIZ SDN BHD | E20: CEP6209 | F20: HBPWO2406002 | G20: 973.08 | H20: 420 | I20: 1393.08 | K20: 1393.08 | L20: WS
A21: HBPSI2406005 | B21: JUNE | C21: 45468 | D21: EDARAN RIZ SDN BHD | E21: QBG8589 | F21: HBPWO2404002 | G21: 55226.49 | H21: 8700 | I21: 63926.49 | K21: 63926.49 | L21: OD
A22: HBPSI2406006 | B22: JUNE | C22: 45472 | D22: EDARAN RIZ SDN BHD | E22: VGK9635 | F22: HBPWO2406004 | H22: 908.2 | I22: 908.2 | K22: 908.2 | M22: FUSO INVOICE
A23: HBPSI2406007 | B23: JUNE | C23: 45472 | D23: EDARAN RIZ SDN BHD | E23: VGK8942 | F23: HBPWO2406005 | H23: 240 | I23: 240 | K23: 240 | M23: FUSO INVOICE
A24: HBPSI2406008 | B24: JUNE | C24: 45472 | D24: EDARAN RIZ SDN BHD | E24: VGU7551 | F24: HBPWO2406006 | H24: 240 | I24: 240 | K24: 240 | M24: FUSO INVOICE
A25: HBPSI2406009 | B25: JUNE | C25: 45472 | D25: EDARAN RIZ SDN BHD | E25: VGW6873 | F25: HBPWO2406007 | H25: 240 | I25: 240 | K25: 240 | M25: FUSO INVOICE
A26: HBPSI2406010 | B26: JUNE | C26: 45472 | D26: EDARAN RIZ SDN BHD | E26: VGS7608 | F26: HBPWO2406008 | H26: 240 | I26: 240 | K26: 240 | M26: FUSO INVOICE
A27: HBPSI2406011 | B27: JUNE | C27: 45472 | D27: EDARAN RIZ SDN BHD | E27: VGT3790 | F27: HBPWO2406009 | H27: 320 | I27: 320 | K27: 320 | M27: FUSO INVOICE
A28: HBPSI2406012 | B28: JUNE | C28: 45472 | D28: EDARAN RIZ SDN BHD | E28: VGN2843 | F28: HBPWO2406010 | H28: 320 | I28: 320 | K28: 320 | M28: FUSO INVOICE
A29: HBPSI2406013 | B29: JUNE | C29: 45472 | D29: EDARAN RIZ SDN BHD | E29: VGL7449 | F29: HBPWO2406011 | H29: 240 | I29: 240 | K29: 240 | M29: FUSO INVOICE
A30: HBPSI2407001 | B30: JULY | C30: 45474 | D30: EDARAN RIZ SDN BHD | E30: JPL5999 | F30: HBPWO2405004 | G30: 11018.99 | H30: 11100 | I30: 22118.99 | K30: 22118.99 | L30: OD
A31: HBPSI2407002 & HBPSI2407004 | B31: JULY | C31: 45478 | D31: EDARAN RIZ SDN BHD | E31: TCK3019 | F31: HBPWO2405008 | G31: 16499.45 | H31: 3000 | I31: 19499.45 | K31: 19499.45 | L31: OD
A32: HBPSI2407003 | B32: JULY | C32: 45489 | D32: OM SRI RAJAH TRADING | E32: QBG8589 | F32: HBPWO2406013 | G32: 3000 | I32: 1750 | J32: 1250 | K32: 1750 | L32: CR
A33: HBPSI2407005 | B33: JULY | C33: 45489 | D33: SHIKH ENTERPRISE | E33: TBX7589 | F33: HBPWO2407004 | G33: 1600 | I33: 1600 | K33: 1600 | L33: CR
A34: HBPSI2407006 | B34: JULY | C34: 45490 | D34: EDARAN RIZ SDN BHD | E34: TBX7589 | F34: HBPWO2405006 | G34: 34108.88 | H34: 4140 | I34: 38248.88 | K34: 38248.88 | L34: OD
A35: HBPSI2407007 | B35: JULY | C35: 45498 | D35: EDARAN RIZ SDN BHD | E35: VGK9635 | F35: HBPWO2407007 | H35: 1912.4 | I35: 1912.4 | K35: 1912.4 | M35: FUSO INVOICE
A36: HBPSI2407008 | B36: JULY | C36: 45498 | D36: EDARAN RIZ SDN BHD | E36: VGN2843 | F36: HBPWO2407008 | H36: 776 | I36: 776 | K36: 776 | M36: FUSO INVOICE
A37: HBPSI2407009 | B37: JULY | C37: 45497 | D37: EDARAN RIZ SDN BHD | E37: VDR7724 | F37: HBPWO2405005 | G37: 39832.73 | H37: 6708 | I37: 46540.73 | K37: 46540.73 | L37: OD
A38: HBPSI2408001 | B38: AUG | C38: 45528 | D38: EDARAN RIZ SDN BHD | E38: JVW2403 | F38: HBPWO2406001 | G38: 39559.6 | H38: 7800 | I38: 47359.6 | K38: 47359.6 | L38: OD
A39: HBPSI2408002 | B39: AUG | C39: 45534 | D39: EDARAN RIZ SDN BHD | E39: WYN442 | F39: HBPWO2407002 | G39: 12384.2 | H39: 3612 | I39: 15996.2 | K39: 15996.2 | L39: OD
A40: HBPSI2409001 | B40: SEP | C40: 45545 | D40: EDARAN RIZ SDN BHD | E40: KEY2569 | F40: HBPWO2407005 | G40: 28810.72 | H40: 8880 | I40: 37690.72 | K40: 37690.72 | L40: OD
...

Sheet FUSO 2024
A1: TRANSNO | B1: MONTH | C1: DATE | D1: CUSTOMER NAME | E1: REG NO | F1: JOBNO | G1: P.TOTAL | H1: L.TOTAL | I1: GTOTAL | J1: RD | K1: TOTAL
A2: FASSI2401001 | B2: JAN | C2: 45304 | D2: LCH TRANSPORT & SERVICE SDN BHD | E2: VKP8555 | F2: FASWO2401001 | I2: 0 | J2: 0 | K2: 0
A3: FASSI2401002 | B3: JAN | C3: 45306 | D3: FU SHENG TRADING | E3: CDE2118 | F3: FASWO2401002 | G3: 789.67 | H3: 240 | I3: 1029.67 | J3: 0 | K3: 1029.67 | L3: CASH
A4: FASSI2401003 | B4: JAN | C4: 45311 | D4: LHL MARKETING | E4: AMR3233 | F4: FASWO2401003 | G4: 304.97 | H4: 114 | I4: 419 | J4: 0.03 | K4: 419 | L4: CASH
A5: FASSI2403001 | B5: MAR | C5: 45352 | D5: FU SHENG TRADING | E5: UKM 2118 | F5: FASWO2402001 | I5: 0 | J5: 0 | K5: 0
A6: FASSI2403002 | B6: MAR | C6: 45359 | D6: REDHA CONSTRUCTIONS | E6: BRM1186 | F6: FASWO2403001 | I6: 0 | J6: 0 | K6: 0
A7: FASSI2403003 | B7: MAR | C7: 45359 | D7: ENG GUAN AGRICULTURE SDN BHD | E7: NDV7169 | F7: FASWO2403002 | I7: 0 | J7: 0 | K7: 0
A8: FASSI2403004 | B8: MAR | C8: 45371 | D8: LCH TRANSPORT & SERVICE SDN BHD | E8: VKP8555 | F8: FASWO2403003 | I8: 0 | J8: 0 | K8: 0
A9: FASSI2403005 | B9: MAR | C9: 45381 | D9: ENG GUAN AGRICULTURE SDN BHD | E9: NDV7169 | F9: FASWO2403006 | G9: 848 | H9: 243 | I9: 1091 | J9: 0 | K9: 1091 | L9: CASH
A10: FASSI2404001 | B10: APR | C10: 45407 | D10: FM GLOBAL LOGISTICS (M) SDN BHD | E10: VHS9530 | F10: FASWO2404001 | G10: 124.5 | H10: 863.8 | I10: 988.3 | J10: 0 | K10: 988.3 | L10: CASH
A11: FASSI2404002 | B11: APR | C11: 45409 | D11: ASMAWI CONSTRUCTION | E11: VLW3392 | F11: FASWO2404002 | I11: 0 | J11: 0 | K11: 0
A12: FASSI2404003 | B12: APR | C12: 45409 | D12: H&M TRANSPORT | E12: RAT9186 | F12: FASWO2403005 | I12: 0 | J12: 0 | K12: 0
A13: FASSI2404004 | B13: APR | C13: 45411 | D13: ENG GUAN AGRICULTURE SDN BHD | E13: NDV7169 | F13: FASWO2404003 | I13: 0 | J13: 0 | K13: 0
A14: FASSI2405001 | B14: MAY | C14: 45440 | D14: H&M TRANSPORT | E14: RAT9186 | F14: FASWO2405001 | I14: 0 | J14: 0 | K14: 0
A15: FASSI2405002 | B15: MAY | C15: 45440 | D15: H&M TRANSPORT | E15: RAT9186 | F15: FASWO2405002 | I15: 0 | J15: 0 | K15: 0
A16: FASSI2406001 | B16: JUNE | C16: 45467 | D16: GOH PENG LENG | E16: PPL7533 | F16: FASWO2406004 | G16: 433.59 | H16: 181.44 | I16: 615 | J16: -0.03 | K16: 615 | L16: CASH
A17: FASSI2406002 | B17: JUNE | C17: 45444 | D17: REDHA CONSTRUCTIONS | E17: BRM1186 | F17: FASWO2406001 | I17: 0 | J17: 0 | K17: 0
A18: FASSI2406003 | B18: JUNE | C18: 45471 | D18: LCH TRANSPORT & SERVICE SDN BHD | E18: VKP8555 | F18: FASWO2406002 | I18: 0 | J18: 0 | K18: 0
A19: FASSI2406004 | B19: JUNE | C19: 45455 | D19: FU SHENG TRADING | E19: UKM 2118 | F19: FASWO2406003 | I19: 0 | J19: 0 | K19: 0
A20: FASSI2406005 | B20: JUNE | C20: 45469 | D20: MOHD RODZUAN BIN BEDOLLAH | E20: MDR5421 | F20: FASWO2406005 | I20: 0 | J20: 0 | K20: 0
A21: FASSI2407001 | B21: JULY | C21: 45488 | D21: YPF SAWIT TRADING | E21: JWC1993 | F21: FASWO2407001 | I21: 0 | J21: 0 | K21: 0
A22: FASSI2407002 | B22: JULY | C22: 45499 | D22: KENASAN TRADINGS | E22: SK5448E | F22: FASWO2407002 | I22: 0 | J22: 0 | K22: 0
A23: FASSI2409001 | B23: SEP | C23: 45537 | D23: REDHA CONSTRUCTIONS | E23: BRM1186 | F23: FASWO2409001 | I23: 0 | J23: 0 | K23: 0
A24: FASSI2409002 | B24: SEP | C24: 45539 | D24: H&M TRANSPORT | E24: RAT9186 | F24: FASWO2409002 | I24: 0 | J24: 0 | K24: 0
A25: FASSI2409003 | B25: SEP | C25: 45558 | D25: ENG GUAN AGRICULTURE SDN BHD | E25: NDV7169 | F25: FASWO2409003 | I25: 0 | J25: 0 | K25: 0
A26: FASSI2409004 | B26: SEP | C26: 45565 | D26: EDARAN RIZ SDN BHD | E26: 7018327 | F26: FASWO2409006 | G26: 407.55 | H26: 1300 | I26: 1707.55 | J26: 0 | K26: 1707.55 | L26: CASH
A27: FASSI2410001 | B27: OCT | C27: 45579 | D27: GOH PENG LENG | E27: PPL7533 | F27: FASWO2410001 | I27: 0 | J27: 0 | K27: 0
A28: FASSI2410002 | B28: OCT | C28: 45593 | D28: GOH PENG LENG | E28: PPL7533 | F28: FASWO2410003 | G28: 321.31 | H28: 280 | I28: 601.3 | J28: -0.01 | K28: 601.3 | L28: CASH
A29: FASSI2411001 | B29: NOV | C29: 45603 | D29: ASMAWI CONSTRUCTION | E29: VLW3392 | F29: FASWO2411001 | I29: 0 | J29: 0 | K29: 0
A30: FASSI2411002 | B30: NOV | C30: 45612 | D30: KENASAN TRADINGS | E30: SK5448E | F30: FASWO2411002 | I30: 0 | J30: 0 | K30: 0
A31: FASSI2411003 | B31: NOV | C31: 45625 | D31: MOHD RODZUAN BIN BEDOLLAH | E31: MDR5421 | F31: FASWO2411003 | I31: 0 | J31: 0 | K31: 0
A32: FASSI2411004 | B32: NOV | C32: 45625 | D32: EDARAN RIZ SDN BHD | E32: VGT3790 | F32: FASWO2411004 | H32: 656 | I32: 656 | J32: 0 | K32: 656 | L32: INV
A33: FASSI2411005 | B33: NOV | C33: 45625 | D33: EDARAN RIZ SDN BHD | E33: VGW6873 | F33: FASWO2411005 | H33: 736 | I33: 736 | J33: 0 | K33: 736 | L33: INV
A34: FASSI2411006 | B34: NOV | C34: 45625 | D34: EDARAN RIZ SDN BHD | E34: VGS7608 | F34: FASWO2411006 | H34: 320 | I34: 320 | J34: 0 | K34: 320 | L34: INV
A35: FASSI2411007 | B35: NOV | C35: 45625 | D35: EDARAN RIZ SDN BHD | E35: VGK8942 | F35: FASWO2411007 | H35: 320 | I35: 320 | J35: 0 | K35: 320 | L35: INV
A36: FASSI2411008 | B36: NOV | C36: 45625 | D36: EDARAN RIZ SDN BHD | E36: VGU7551 | F36: FASWO2411008 | H36: 320 | I36: 320 | J36: 0 | K36: 320 | L36: INV
A37: FASSI2411009 | B37: NOV | C37: 45625 | D37: EDARAN RIZ SDN BHD | E37: VGL7449 | F37: FASWO2411009 | H37: 240 | I37: 240 | J37: 0 | K37: 240 | L37: INV
A38: FASSI2411010 | B38: NOV | C38: 45625 | D38: EDARAN RIZ SDN BHD | E38: VGK9635 | F38: FASWO2411010 | H38: 472 | I38: 472 | J38: 0 | K38: 472 | L38: INV
A39: FASSI2411011 | B39: NOV | C39: 45625 | D39: EDARAN RIZ SDN BHD | E39: VGN2843 | F39: FASWO2411011 | H39: 392 | I39: 392 | J39: 0 | K39: 392 | L39: INV
A40: FASSI2411012 | B40: NOV | C40: 45626 | D40: LHL MARKETING | E40: AMR3233 | F40: FASWO2408001 | I40: 0 | J40: 0 | K40: 0
...

Sheet FUSO WC 2024
A1: WARRANTY CLAIM LISTING
A2: DATE | B2: MONTH | C2: CLAIM NO | D2: CLAIM TO | E2: INVOICE NO | F2: REGNO | G2: PART | H2: LABOUR | I2: TOTAL | J2: AMOUNT
A3: 45371 | B3: MAR | C3: FASWC2403001 | D3: HAP SENG TRUCK DISTRIBUTION SDN BHD | E3: FASSI2403004 | F3: VKP8555 | G3: 148.8 | H3: 56.88 | I3: 205.68 | J3: 205.68
A4: 45411 | B4: APR | C4: FASWC2404001 | D4: HAP SENG TRUCK DISTRIBUTION SDN BHD | E4: FASSI2404004 | F4: NDV7169 | G4: 2867.57 | H4: 450 | I4: 3317.57 | J4: 3317.57
A5: 45440 | B5: MAY | C5: FASWC2405001 | D5: HAP SENG TRUCK DISTRIBUTION SDN BHD | E5: FASSI2405002 | F5: RAT9186 | G5: 327.36 | H5: 42 | I5: 369.36 | J5: 369.36
A6: 45579 | B6: OCT | C6: FASWC2410001 | D6: HAP SENG TRUCK DISTRIBUTION SDN BHD | E6: FASSI2410001 | F6: PPL7533 | G6: 1824.24 | H6: 96 | I6: 1920.24 | J6: 1920.24
A7: 45602 | B7: NOV | C7: FASWC2411001 | D7: HAP SENG TRUCK DISTRIBUTION SDN BHD | E7: FASSI2411012 | F7: AMR3233 | G7: 409.2 | H7: 252 | I7: 661.2 | J7: 661.2
J9: =SUM(J3:J8) -> 6474.05
A11: FREE SERVICE
A12: 45304 | B12: JAN | C12: FASFS2401001 | D12: HAP SENG TRUCK DISTRIBUTION SDN BHD | E12: FASSI2401001 | F12: VKP8555 | G12: 240.21 | H12: 108 | I12: 348.21 | J12: 348.21
A13: 45358 | B13: MAR | C13: FASFS2403001 | D13: HAP SENG TRUCK DISTRIBUTION SDN BHD | E13: FASSI2403001 | F13: UKM 2118 | G13: 225.81 | H13: 126 | I13: 351.81 | J13: 351.81
A14: 45359 | B14: MAR | C14: FASFS2403002 | D14: HAP SENG TRUCK DISTRIBUTION SDN BHD | E14: FASSI2403002 | F14: BRM1186 | G14: 225.81 | H14: 126 | I14: 351.81 | J14: 351.81
A15: 45359 | B15: MAR | C15: FASFS2403003 | D15: HAP SENG TRUCK DISTRIBUTION SDN BHD | E15: FASSI2403003 | F15: NDV7169 | G15: 501.18 | H15: 222 | I15: 723.18 | J15: 723.18
A16: 45409 | B16: APR | C16: FASFS2404001 | D16: HAP SENG TRUCK DISTRIBUTION SDN BHD | E16: FASSI2404002 | F16: VLW3392 | G16: 395.23 | H16: 180 | I16: 575.23 | J16: 575.23
A17: 45409 | B17: APR | C17: FASFS2404002 | D17: HAP SENG TRUCK DISTRIBUTION SDN BHD | E17: FASSI2404003 | F17: RAT9186 | G17: 494.18 | H17: 198 | I17: 692.18 | J17: 692.18
A18: 45440 | B18: MAY | C18: FASFS2405001 | D18: HAP SENG TRUCK DISTRIBUTION SDN BHD | E18: FASSI2405001 | F18: RAT9186 | G18: 225.81 | H18: 126 | I18: 351.81 | J18: 351.81
A19: 45444 | B19: JUNE | C19: FASFS2406001 | D19: HAP SENG TRUCK DISTRIBUTION SDN BHD | E19: FASSI2406002 | F19: BRM1186 | G19: 240.21 | H19: 108 | I19: 348.21 | J19: 348.21
A20: 45471 | B20: JUNE | C20: FASFS2406002 | D20: HAP SENG TRUCK DISTRIBUTION SDN BHD | E20: FASSI2406003 | F20: VKP8555 | G20: 501.18 | H20: 222 | I20: 723.18 | J20: 723.18
A21: 45455 | B21: JUNE | C21: FASFS2406003 | D21: HAP SENG TRUCK DISTRIBUTION SDN BHD | E21: FASSI2406004 | F21: UKM 2118 | G21: 240.21 | H21: 108 | I21: 348.21 | J21: 348.21
A22: 45469 | B22: JUNE | C22: FASFS2406004 | D22: HAP SENG TRUCK DISTRIBUTION SDN BHD | E22: FASSI2406005 | F22: MDR5421 | G22: 240.21 | H22: 108 | I22: 348.21 | J22: 348.21
A23: 45482 | B23: JULY | C23: FASFS2407001 | D23: HAP SENG TRUCK DISTRIBUTION SDN BHD | E23: FASSI2407001 | F23: JWC1993 | G23: 240.21 | H23: 108 | I23: 348.21 | J23: 348.21
... A31: 45639 | B31: DEC | C31: FASFS2412001 | D31: HAP SENG TRUCK DISTRIBUTION SDN BHD | E31: FASSI2412001 | F31: BRM1186 | G31: 325.01 | H31: 120 | I31: 445.01 | J31: 445.01
J33: =SUM(J12:J32) -> 9590.64

Sheet 2025
B1: Auto Raya Sdn Bhd
B2: Monthly Summary After Sales 2025
C4: HINO
C5: ACCIDENT | H5: WINDSCREEN | M5: OTHERS | P5: TOTAL
C6: INTAKE | D6: INS - PARTS | E6: INS - LABOURS | F6: CREDIT | G6: CASH | H6: INTAKE | I6: INS - PARTS | J6: INS - LABOURS | K6: CREDIT | L6: CASH | M6: INTAKE | N6: CASH | O6: CREDIT | P6: INTAKE | Q6: TOTAL | R6: Avg
B7: JANUARY | C7: 2 | D7: ='HINO 2025'!G2+'HINO 2025'!G3 -> 62208.69 | E7: ='HINO 2025'!H2+'HINO 2025'!H3 -> 19860 | F7: 950 | G7: 0 | H7: 1 | I7: ='HINO 2025'!G4 -> 908.52 | J7: ='HINO 2025'!H4 -> 480 | K7: 0 | L7: 0 | M7: 0 | N7: 0 | O7: 0 | P7: =SUM(C7+H7+M7) -> 3 | Q7: =D7+E7+F7+G7+I7+J7+L7+K7+N7+O7 -> 84407.21 | R7: =Q7/P7 -> 28135.737
B8: FEBRUARY | C8: 5 | D8: ='HINO 2025'!G5+'HINO 2025'!G6+'HINO 2025'!G8+'HINO 2025'!G9+'HINO 2025'!G10 -> 102728.34 | E8: ='HINO 2025'!H5+'HINO 2025'!H6+'HINO 2025'!H8+'HINO 2025'!H9+'HINO 2025'!H10 -> 14760 | F8: 2280 | G8: 0 | H8: 1 | I8: ='HINO 2025'!G7 -> 973.08 | J8: ='HINO 2025'!H7 -> 420 | K8: 0 | L8: 0 | M8: 0 | N8: 0 | O8: 0 | P8: =SUM(C8+H8+M8) -> 6 | Q8: =D8+E8+F8+G8+I8+J8+L8+K8+N8+O8 -> 121161.42 | R8: =Q8/P8 -> 20193.57
B9: MARCH | C9: 1 | D9: ='HINO 2025'!G13 -> 110273.46 | E9: ='HINO 2025'!H13 -> 5028 | F9: 0 | G9: 0 | H9: 3 | I9: ='HINO 2025'!G11+'HINO 2025'!G12+'HINO 2025'!G14 -> 2634.24 | J9: ='HINO 2025'!H11+'HINO 2025'!H12+'HINO 2025'!H14 -> 1260 | K9: 0 | L9: 0 | M9: 0 | N9: 0 | O9: 0 | P9: =SUM(C9+H9+M9) -> 4 | Q9: =D9+E9+F9+G9+I9+J9+L9+K9+N9+O9 -> 119195.7 | R9: =Q9/P9 -> 29798.925
B10: APRIL | C10: 4 | D10: 204242.82 | E10: 16848 | F10: 2907 | G10: 0 | H10: 0 | I10: 0 | J10: 0 | K10: 0 | L10: 0 | M10: 0 | N10: 0 | O10: 0 | P10: =SUM(C10+H10+M10) -> 4 | Q10: =D10+E10+F10+G10+I10+J10+L10+K10+N10+O10 -> 223997.82 | R10: =Q10/P10 -> 55999.455
B11: MAY | C11: 3 | D11: 39133.91 | E11: 21360 | F11: 6615.37 | G11: 0 | H11: 1 | I11: 973.08 | J11: 420 | K11: 0 | L11: 0 | M11: 1 | N11: 975 | P11: =SUM(C11+H11+M11) -> 5 | Q11: =D11+E11+F11+G11+I11+J11+L11+K11+N11+O11 -> 69477.36 | R11: =Q11/P11 -> 13895.472
B12: JUNE | C12: 3 | D12: 92302.72 | E12: 13246.8 | F12: 6378 | G12: 0 | H12: 0 | I12: 0 | J12: 0 | K12: 0 | L12: 0 | M12: 0 | N12: 0 | O12: 0 | P12: =SUM(C12+H12+M12) -> 3 | Q12: =D12+E12+F12+G12+I12+J12+L12+K12+N12+O12 -> 111927.52 | R12: =Q12/P12 -> 37309.173
B13: JULY | C13: 7 | D13: 272907.57 | E13: 31188 | F13: 2261 | G13: 0 | H13: 2 | I13: 2231.16 | J13: 840 | K13: 0 | L13: 0 | M13: 0 | N13: 0 | O13: 0 | P13: =SUM(C13+H13+M13) -> 9 | Q13: =D13+E13+F13+G13+I13+J13+L13+K13+N13+O13 -> 309427.73 | R13: =Q13/P13 -> 34380.859
B14: AUGUST | C14: 2 | D14: 10050.07 | E14: 4389 | F14: 0 | G14: 0 | H14: 2 | I14: 1887.84 | J14: 627 | K14: 0 | L14: 0 | M14: 0 | N14: 0 | O14: 0 | P14: =SUM(C14+H14+M14) -> 4 | Q14: =D14+E14+F14+G14+I14+J14+L14+K14+N14+O14 -> 16953.91 | R14: =Q14/P14 -> 4238.4775
B15: SEPTEMBER | C15: 4 | D15: 82294.18 | E15: 16188 | F15: 3935 | G15: 0 | H15: 1 | I15: 994.08 | J15: 399 | K15: 0 | L15: 0 | M15: 2 | N15: 7060 | O15: 0 | P15: =SUM(C15+H15+M15) -> 7 | Q15: =D15+E15+F15+G15+I15+J15+L15+K15+N15+O15 -> 110870.26 | R15: =Q15/P15 -> 15838.609
B16: OCTOBER | C16: 6 | D16: 157880.89 | E16: 29979.15 | F16: 0 | G16: 0 | H16: 3 | I16: 2032.24 | J16: 1197 | K16: 0 | L16: 0 | M16: 0 | N16: 0 | O16: 0 | P16: =SUM(C16+H16+M16) -> 9 | Q16: =D16+E16+F16+G16+I16+J16+L16+K16+N16+O16 -> 191089.28 | R16: =Q16/P16 -> 21232.142
B17: NOVEMBER | C17: 6 | D17: 171427.56 | E17: 35017.38 | F17: 9520 | G17: 0 | H17: 2 | I17: 658.16 | J17: 798 | K17: 0 | L17: 0 | M17: 0 | N17: 0 | O17: 0 | P17: =SUM(C17+H17+M17) -> 8 | Q17: =D17+E17+F17+G17+I17+J17+L17+K17+N17+O17 -> 217421.1 | R17: =Q17/P17 -> 27177.638
B18: DECEMBER | C18: 3 | D18: 82793.62 | E18: 18616.2 | F18: 950 | G18: 0 | H18: 0 | I18: 0 | J18: 0 | K18: 0 | L18: 0 | M18: 0 | N18: 0 | O18: 0 | P18: =SUM(C18+H18+M18) -> 3 | Q18: =D18+E18+F18+G18+I18+J18+L18+K18+N18+O18 -> 102359.82 | R18: =Q18/P18 -> 34119.94
C19: =SUM(C7:C18) -> 46 | D19: =SUM(D7:D18) -> 1388243.8 | E19: =SUM(E7:E18) -> 226480.53 | F19: =SUM(F7:F18) -> 35796.37 | G19: =SUM(G7:G18) -> 0 | H19: =SUM(H7:H18) -> 16 | I19: =SUM(I7:I18) -> 13292.4 | J19: =SUM(J7:J18) -> 6441 | ... Q19: =SUM(Q7:Q18) -> 1678289.1 | R19: =Q19/P19 -> 25819.833
C22: MITSUBISHI
C23: ACCIDENT | H23: WINDSCREEN | M23: OTHERS | P23: TOTAL
C24: INTAKE | D24: INS - PARTS | E24: INS - LABOURS | F24: CREDIT | G24: CASH | H24: INTAKE | I24: INS - PARTS | J24: INS - LABOURS | K24: CREDIT | L24: CASH | M24: INTAKE | N24: CASH | O24: CREDIT | P24: INTAKE | Q24: TOTAL | R24: Avg
B25: JANUARY | C25: 10 | D25: ='MITS 2025'!G2+'MITS 2025'!G4+'MITS 2025'!G5+'MITS 2025'!G7+'MITS 2025'!G8+'MITS 2025'!G11+'MITS 2025'!G12+'MITS 2025'!G13+'MITS 2025'!G14+'MITS 2025'!G15 -> 98603.04 | E25: ='MITS 2025'!H2+'MITS 2025'!H4+'MITS 2025'!H5+'MITS 2025'!H7+'MITS 2025'!H8+'MITS 2025'!H11+'MITS 2025'!H12+'MITS 2025'!H13+'MITS 2025'!H14+'MITS 2025'!H15 -> 36816 | F25: 0 | G25: ='MITS 2025'!K9 -> 515 | H25: 2 | I25: ='MITS 2025'!G3+'MITS 2025'!G6 -> 4181.87 | J25: ='MITS 2025'!H3+'MITS 2025'!H6 -> 528 | K25: 0 | L25: 0 | M25: 1 | N25: 0 | O25: ='MITS 2025'!K10 -> 115 | P25: =SUM(C25+H25+M25) -> 13 | Q25: =D25+E25+F25+G25+I25+J25+K25+L25+N25+O25 -> 140758.91 | R25: =Q25/P25 -> 10827.608
B26: FEBRUARY | C26: 8 | D26: ='MITS 2025'!G16+'MITS 2025'!G17+'MITS 2025'!G20+'MITS 2025'!G23+'MITS 2025'!G24+'MITS 2025'!G25+'MITS 2025'!G26+'MITS 2025'!G27 -> 88403.77 | E26: ='MITS 2025'!H16+'MITS 2025'!H17+'MITS 2025'!H20+'MITS 2025'!H23+'MITS 2025'!H24+'MITS 2025'!H25+'MITS 2025'!H26+'MITS 2025'!H27 -> 27570 | F26: 0 | G26: 0 | H26: 4 | I26: ='MITS 2025'!G18+'MITS 2025'!G19+'MITS 2025'!G21+'MITS 2025'!G28 -> 7232.75 | J26: ='MITS 2025'!H18+'MITS 2025'!H19+'MITS 2025'!H21+'MITS 2025'!H28 -> 1068 | K26: 0 | L26: 350 | M26: 1 | N26: ='MITS 2025'!K22 -> 1603.8 | O26: 0 | P26: =SUM(C26+H26+M26) -> 13 | Q26: =D26+E26+F26+G26+I26+J26+K26+L26+N26+O26 -> 126228.32 | R26: =Q26/P26 -> 9709.8708
B27: MARCH | C27: 9 | D27: ='MITS 2025'!G29+'MITS 2025'!G30+'MITS 2025'!G37+'MITS 2025'!G35+'MITS 2025'!G38+'MITS 2025'!G39+'MITS 2025'!G42+'MITS 2025'!G43+'MITS 2025'!G44 -> 78790.87 | E27: ='MITS 2025'!H29+'MITS 2025'!H30+'MITS 2025'!H37+'MITS 2025'!H35+'MITS 2025'!H38+'MITS 2025'!H39+'MITS 2025'!H42+'MITS 2025'!H43+'MITS 2025'!H44 -> 26745.6 | F27: 1977.05 | G27: 0 | H27: 6 | I27: ='MITS 2025'!G31+'MITS 2025'!G32+'MITS 2025'!G33+'MITS 2025'!G36+'MITS 2025'!G40+'MITS 2025'!G41 -> 14086.82 | J27: ='MITS 2025'!H31+'MITS 2025'!H32+'MITS 2025'!H33+'MITS 2025'!H36+'MITS 2025'!H40+'MITS 2025'!H41 -> 1476 | K27: 1027.98 | L27: 0 | M27: 1 | N27: ='MITS 2025'!K34 -> 1242.2 | O27: 0 | P27: =SUM(C27+H27+M27) -> 16 | Q27: =D27+E27+F27+G27+I27+J27+K27+L27+N27+O27 -> 125346.52 | R27: =Q27/P27 -> 7834.1575
B28: APRIL | C28: 4 | D28: 38080.99 | E28: 9636 | F28: 1805 | G28: 0 | H28: 6 | I28: 15145.54 | J28: 1536 | K28: 179.74 | L28: 0 | M28: 0 | N28: 0 | O28: 0 | P28: =SUM(C28+H28+M28) -> 10 | Q28: =D28+E28+F28+G28+I28+J28+K28+L28+N28+O28 -> 66383.27 | R28: =Q28/P28 -> 6638.327
B29: MAY | C29: 4 | D29: 59154.41 | E29: 22044 | F29: 0 | G29: 0 | H29: 5 | I29: 10917.52 | J29: 1260 | K29: 353.55 | L29: 0 | M29: 3 | N29: 5151.9 | O29: 7046.72 | P29: =SUM(C29+H29+M29) -> 12 | Q29: =D29+E29+F29+G29+I29+J29+K29+L29+N29+O29 -> 105928.1 | R29: =Q29/P29 -> 8827.3417
B30: JUNE | C30: 8 | D30: 125740.31 | E30: 33924 | F30: 2520.16 | G30: 0 | H30: 3 | I30: 7373.44 | J30: 804 | K30: 0 | L30: 0 | M30: 5 | N30: 2401 | O30: 6690.53 | P30: =SUM(C30+H30+M30) -> 16 | Q30: =D30+E30+F30+G30+I30+J30+K30+L30+N30+O30 -> 179453.44 | R30: =Q30/P30 -> 11215.84
B31: JULY | C31: 5 | D31: 52374.98 | E31: 18828 | F31: 2185 | G31: 0 | H31: 9 | I31: 18701.7 | J31: 2304 | K31: 501.92 | L31: 0 | M31: 1 | N31: 0 | O31: 6409.65 | P31: =SUM(C31+H31+M31) -> 15 | Q31: =D31+E31+F31+G31+I31+J31+K31+L31+N31+O31 -> 101305.25 | R31: =Q31/P31 -> 6753.6833
B32: AUGUST | C32: 4 | D32: 50679.19 | E32: 10442.4 | F32: 1690.05 | G32: 0 | H32: 10 | I32: 19128.34 | J32: 2485.2 | K32: 539.65 | L32: 0 | M32: 1 | N32: 0 | O32: 676 | P32: =SUM(C32+H32+M32) -> 15 | Q32: =D32+E32+F32+G32+I32+J32+K32+L32+N32+O32 -> 85640.83 | R32: =Q32/P32 -> 5709.3887
B33: SEPTEMBER | C33: 6 | D33: 121390.93 | E33: 25182.6 | F33: 3531.15 | G33: 0 | H33: 4 | I33: 7771.57 | J33: 809.4 | K33: 99.94 | L33: 0 | M33: 0 | N33: 0 | O33: 0 | P33: =SUM(C33+H33+M33) -> 10 | Q33: =D33+E33+F33+G33+I33+J33+K33+L33+N33+O33 -> 158785.59 | R33: =Q33/P33 -> 15878.559
B34: OCTOBER | C34: 6 | D34: 112833.75 | E34: 28078.2 | F34: 75.95 | G34: 0 | H34: 5 | I34: 8150.69 | J34: 1242.6 | K34: 410.48 | L34: 0 | M34: 2 | N34: 93 | O34: 136.6 | P34: =SUM(C34+H34+M34) -> 13 | Q34: =D34+E34+F34+G34+I34+J34+K34+L34+N34+O34 -> 151021.27 | R34: =Q34/P34 -> 11617.021
B35: NOVEMBER | C35: 4 | D35: 87613.38 | E35: 12961.8 | F35: 0 | G35: 0 | H35: 6 | I35: 13755.31 | J35: 1447.8 | K35: 172.98 | L35: 0 | M35: 0 | N35: 0 | O35: 0 | P35: =SUM(C35+H35+M35) -> 10 | Q35: =D35+E35+F35+G35+I35+J35+K35+L35+N35+O35 -> 115951.27 | R35: =Q35/P35 -> 11595.127
B36: DECEMBER | C36: 6 | D36: 95400.75 | E36: 19191.9 | F36: 370.5 | G36: 0 | H36: 7 | I36: 10956.79 | J36: 1637.8 | K36: 1008.22 | L36: 0 | M36: 1 | N36: 962 | O36: 0 | P36: =SUM(C36+H36+M36) -> 14 | Q36: =D36+E36+F36+G36+I36+J36+K36+L36+N36+O36 -> 129527.96 | R36: =Q36/P36 -> 9251.9971
C37: =SUM(C25:C36) -> 74 | D37: =SUM(D25:D36) -> 1009066.4 | E37: =SUM(E25:E36) -> 271420.5 | F37: =SUM(F25:F36) -> 14154.86 | G37: =SUM(G25:G36) -> 515 | H37: =SUM(H25:H36) -> 67 | I37: =SUM(I25:I36) -> 137402.34 | J37: =SUM(J25:J36) -> 16598.8 | ... Q37: =SUM(Q25:Q36) -> 1486330.7 | R37: =Q37/P37 -> 9467.0747
C40: AFTER SALES SERVICE
C41: SERVICE FUSO | M41: SERVICE HINO | P41: TOTAL
C42: INTAKE | D42: FREE SERVICE | G42: INTAKE | H42: WARRANTY | I42: INTAKE | L42: CASH | M42: INTAKE | N42: INVOICE | O42: CASH | P42: INTAKE | Q42: TOTAL | R42: Avg
B43: JANUARY | C43: 2 | D43: ='FUSO WC 2025'!J21+'FUSO WC 2025'!J22 -> 1446.36 | G43: 0 | H43: 0 | I43: 2 | L43: ='FUSO 2025'!L3+'FUSO 2025'!L5 -> 549.5 | M43: 0 | N43: 0 | O43: 0 | P43: =SUM(C43+G43+I43+M43) -> 4 | Q43: =SUM(D43+H43+L43+N43+O43) -> 1995.86 | R43: =Q43/P43 -> 498.965
B44: FEBRUARY | C44: 2 | D44: ='FUSO WC 2025'!J23+'FUSO WC 2025'!J24 -> 696.42 | G44: 1 | H44: ='FUSO WC 2025'!J3 -> 1544.76 | I44: 0 | L44: 0 | M44: 0 | N44: 0 | O44: 0 | P44: =SUM(C44+G44+I44+M44) -> 3 | Q44: =SUM(D44+H44+L44+N44+O44) -> 2241.18 | R44: =Q44/P44 -> 747.06
B45: MARCH | C45: 1 | D45: ='FUSO WC 2025'!J25 -> 453.01 | G45: 1 | H45: ='FUSO WC 2025'!J4 -> 369.36 | I45: 3 | L45: ='FUSO 2025'!L9+'FUSO 2025'!L10+'FUSO 2025'!L11 -> 1402.1 | M45: 0 | N45: 0 | O45: 0 | P45: =SUM(C45+G45+I45+M45) -> 5 | Q45: =SUM(D45+H45+L45+N45+O45) -> 2224.47 | R45: =Q45/P45 -> 444.894
...

Sheet 2026
B1: Auto Raya Sdn Bhd
B2: Monthly Summary After Sales 2026
C4: HINO
C5: ACCIDENT | H5: WINDSCREEN | M5: OTHERS | P5: TOTAL
C6: INTAKE | D6: INS - PARTS | E6: INS - LABOURS | F6: CREDIT | G6: CASH | H6: INTAKE | I6: INS - PARTS | J6: INS - LABOURS | K6: CREDIT | L6: CASH | M6: INTAKE | N6: CASH | O6: CREDIT | P6: INTAKE | Q6: TOTAL | R6: Avg
B7: JANUARY | C7: 6 | D7: 182814.26 | E7: 26744.4 | F7: 7700 | G7: 0 | H7: 1 | I7: 994.08 | J7: 399 | K7: 0 | L7: 0 | M7: 0 | N7: 0 | O7: 0 | P7: =SUM(C7+H7+M7) -> 7 | Q7: =D7+E7+F7+G7+I7+J7+L7+K7+N7+O7 -> 218651.74 | R7: =Q7/P7 -> 31235.963
B8: FEBRUARY | C8: 6 | D8: 190831.86 | E8: 31717.8 | F8: 2375 | G8: 0 | H8: 1 | I8: 994.08 | J8: 399 | K8: 0 | L8: 0 | M8: 1 | N8: 800 | O8: 0 | P8: =SUM(C8+H8+M8) -> 8 | Q8: =D8+E8+F8+G8+I8+J8+L8+K8+N8+O8 -> 227117.74 | R8: =Q8/P8 -> 28389.717
B9: MARCH | C9: 0 | D9: 0 | E9: 0 | F9: 0 | G9: 0 | H9: 1 | I9: 994.08 | J9: 399 | K9: 0 | L9: 0 | M9: 1 | N9: 2664 | O9: 0 | P9: =SUM(C9+H9+M9) -> 2 | Q9: =D9+E9+F9+G9+I9+J9+L9+K9+N9+O9 -> 4057.08 | R9: =Q9/P9 -> 2028.54
B10: APRIL | C10: 1 | D10: 2762.89 | E10: 3306 | F10: 500 | G10: 0 | H10: 0 | I10: 0 | J10: 0 | K10: 0 | L10: 0 | M10: 0 | N10: 0 | O10: 0 | P10: =SUM(C10+H10+M10) -> 1 | Q10: =D10+E10+F10+G10+I10+J10+L10+K10+N10+O10 -> 6568.89 | R10: =Q10/P10 -> 6568.89
B11: MAY | C11: 2 | D11: 83670.26 | E11: 15173.4 | F11: 2550 | G11: 0 | H11: 0 | I11: 0 | J11: 0 | K11: 0 | L11: 0 | M11: 0 | N11: 0 | O11: 0 | P11: =SUM(C11+H11+M11) -> 2 | Q11: =D11+E11+F11+G11+I11+J11+L11+K11+N11+O11 -> 101393.66 | R11: =Q11/P11 -> 50696.83
B12: JUNE | C12: 3 | D12: 185938.63 | E12: 17613 | F12: 0 | H12: 2 | I12: 2273.16 | J12: 798 | K12: 0 | L12: 0 | M12: 0 | N12: 0 | O12: 0 | P12: =SUM(C12+H12+M12) -> 5 | Q12: =D12+E12+F12+G12+I12+J12+L12+K12+N12+O12 -> 206622.79 | R12: =Q12/P12 -> 41324.558
B13: JULY | C13: 2 | D13: 72864.52 | E13: 24681 | F13: 0 | G13: 0 | H13: 0 | I13: 0 | J13: 0 | K13: 0 | L13: 0 | M13: 1 | N13: 5620 | O13: 0 | P13: =SUM(C13+H13+M13) -> 3 | Q13: =D13+E13+F13+G13+I13+J13+L13+K13+N13+O13 -> 103165.52 | R13: =Q13/P13 -> 34388.507
B14: AUGUST | C14: 3 | D14: 145249.87 | E14: 20052.6 | F14: 2437.5 | G14: 0 | H14: 0 | I14: 0 | J14: 0 | K14: 0 | L14: 0 | M14: 0 | N14: 0 | O14: 0 | P14: =SUM(C14+H14+M14) -> 3 | Q14: =D14+E14+F14+G14+I14+J14+L14+K14+N14+O14 -> 167739.97 | R14: =Q14/P14 -> 55913.323
B15: SEPTEMBER | C15: 1 | D15: 59446.52 | E15: 5814 | F15: 3515 | G15: 0 | H15: 1 | I15: 994.08 | J15: 399 | K15: 0 | L15: 0 | M15: 0 | N15: 0 | O15: 0 | P15: =SUM(C15+H15+M15) -> 2 | Q15: =D15+E15+F15+G15+I15+J15+L15+K15+N15+O15 -> 70168.6 | R15: =Q15/P15 -> 35084.3
B16: OCTOBER | P16: =SUM(C16+H16+M16) -> 0 | Q16: =D16+E16+F16+G16+I16+J16+L16+K16+N16+O16 -> 0 | R16: =Q16/P16 -> #DIV/0!
B17: NOVEMBER | P17: =SUM(C17+H17+M17) -> 0 | Q17: =D17+E17+F17+G17+I17+J17+L17+K17+N17+O17 -> 0 | R17: =Q17/P17 -> #DIV/0!
B18: DECEMBER | P18: =SUM(C18+H18+M18) -> 0 | Q18: =D18+E18+F18+G18+I18+J18+L18+K18+N18+O18 -> 0 | R18: =Q18/P18 -> #DIV/0!
C19: =SUM(C7:C18) -> 24 | D19: =SUM(D7:D18) -> 923578.81 | E19: =SUM(E7:E18) -> 145102.2 | F19: =SUM(F7:F18) -> 19077.5 | G19: =SUM(G7:G18) -> 0 | H19: =SUM(H7:H18) -> 6 | I19: =SUM(I7:I18) -> 6249.48 | J19: =SUM(J7:J18) -> 2394 | ... Q19: =SUM(Q7:Q18) -> 1105486 | R19: =Q19/P19 -> 33499.575
C22: MITSUBISHI
C23: ACCIDENT | H23: WINDSCREEN | M23: OTHERS | P23: TOTAL
C24: INTAKE | D24: INS - PARTS | E24: INS - LABOURS | F24: CREDIT | G24: CASH | H24: INTAKE | I24: INS - PARTS | J24: INS - LABOURS | K24: CREDIT | L24: CASH | M24: INTAKE | N24: CASH | O24: CREDIT | P24: INTAKE | Q24: TOTAL | R24: Avg
B25: JANUARY | C25: 7 | D25: 76626.36 | E25: 21295.2 | F25: 1868.65 | G25: 0 | H25: 8 | I25: 14982.87 | J25: 1881 | K25: 0 | L25: 0 | M25: 1 | N25: 1560 | O25: 0 | P25: =SUM(C25+H25+M25) -> 16 | Q25: =D25+E25+F25+G25+I25+J25+K25+L25+N25+O25 -> 118214.08 | R25: =Q25/P25 -> 7388.38
B26: FEBRUARY | C26: 3 | D26: 81784.47 | E26: 21922.2 | F26: 2375 | G26: 0 | H26: 1 | I26: 2091.82 | J26: 262.2 | K26: 0 | L26: 0 | M26: 0 | N26: 0 | O26: 0 | P26: =SUM(C26+H26+M26) -> 4 | Q26: =D26+E26+F26+G26+I26+J26+K26+L26+N26+O26 -> 108435.69 | R26: =Q26/P26 -> 27108.923
B27: MARCH | C27: 3 | D27: 35006.71 | E27: 7706.4 | F27: 0 | G27: 0 | H27: 0 | I27: 0 | J27: 0 | K27: 172.98 | L27: 0 | M27: 2 | N27: 649.9 | O27: 4551.26 | P27: =SUM(C27+H27+M27) -> 5 | Q27: =D27+E27+F27+G27+I27+J27+K27+L27+N27+O27 -> 48087.25 | R27: =Q27/P27 -> 9617.45
B28: APRIL | C28: 5 | D28: 52416.14 | E28: 13474.8 | F28: 2411.69 | G28: 0 | H28: 6 | I28: 13219.85 | J28: 1504.8 | K28: 0 | L28: 0 | M28: 3 | N28: 0 | O28: 20263.86 | P28: =SUM(C28+H28+M28) -> 14 | Q28: =D28+E28+F28+G28+I28+J28+K28+L28+N28+O28 -> 103291.14 | R28: =Q28/P28 -> 7377.9386
B29: MAY | C29: 10 | D29: 153504.63 | E29: 34108.8 | F29: 2061.7 | G29: 0 | H29: 2 | I29: 5165.15 | J29: 490.2 | K29: 0 | L29: 0 | M29: 0 | N29: 0 | O29: 0 | P29: =SUM(C29+H29+M29) -> 12 | Q29: =D29+E29+F29+G29+I29+J29+K29+L29+N29+O29 -> 195330.48 | R29: =Q29/P29 -> 16277.54
B30: JUNE | C30: 3 | D30: 25784.15 | E30: 14763 | F30: 1527 | H30: 3 | I30: 6214.63 | J30: 752.4 | K30: 172.98 | L30: 0 | M30: 2 | N30: 0 | O30: 2843.9 | P30: =SUM(C30+H30+M30) -> 8 | Q30: =D30+E30+F30+G30+I30+J30+K30+L30+N30+O30 -> 52058.06 | R30: =Q30/P30 -> 6507.2575
B31: JULY | C31: 4 | D31: 71069.6 | E31: 11947.2 | F31: 0 | G31: 0 | H31: 3 | I31: 7169.65 | J31: 815.1 | K31: 30 | L31: 0 | M31: 0 | N31: 0 | O31: 0 | P31: =SUM(C31+H31+M31) -> 7 | Q31: =D31+E31+F31+G31+I31+J31+K31+L31+N31+O31 -> 91031.55 | R31: =Q31/P31 -> 13004.507
B32: AUGUST | C32: 8 | D32: 160868.59 | E32: 33504.6 | F32: 1028.85 | G32: 0 | H32: 4 | I32: 8499.22 | J32: 1014.6 | K32: 0 | L32: 0 | M32: 2 | N32: 0 | O32: 12756.45 | P32: =SUM(C32+H32+M32) -> 14 | Q32: =D32+E32+F32+G32+I32+J32+K32+L32+N32+O32 -> 217672.31 | R32: =Q32/P32 -> 15548.022
B33: SEPTEMBER | C33: 2 | D33: 16887.58 | E33: 3283.2 | F33: 0 | G33: 0 | H33: 2 | I33: 4198.81 | J33: 490.2 | K33: 337.44 | L33: 0 | M33: 4 | N33: 390 | O33: 3967.88 | P33: =SUM(C33+H33+M33) -> 8 | Q33: =D33+E33+F33+G33+I33+J33+K33+L33+N33+O33 -> 29555.11 | R33: =Q33/P33 -> 3694.3888
B34: OCTOBER | P34: =SUM(C34+H34+M34) -> 0 | Q34: =D34+E34+F34+G34+I34+J34+K34+L34+N34+O34 -> 0 | R34: =Q34/P34 -> #DIV/0!
B35: NOVEMBER | P35: =SUM(C35+H35+M35) -> 0 | Q35: =D35+E35+F35+G35+I35+J35+K35+L35+N35+O35 -> 0 | R35: =Q35/P35 -> #DIV/0!
B36: DECEMBER | P36: =SUM(C36+H36+M36) -> 0 | Q36: =D36+E36+F36+G36+I36+J36+K36+L36+N36+O36 -> 0 | R36: =Q36/P36 -> #DIV/0!
C37: =SUM(C25:C36) -> 45 | D37: =SUM(D25:D36) -> 673948.23 | E37: =SUM(E25:E36) -> 162005.4 | F37: =SUM(F25:F36) -> 11272.89 | G37: =SUM(G25:G36) -> 0 | H37: =SUM(H25:H36) -> 29 | I37: =SUM(I25:I36) -> 61542 | J37: =SUM(J25:J36) -> 7210.5 | ... Q37: =SUM(Q25:Q36) -> 963675.67 | R37: =Q37/P37 -> 10950.86
C40: AFTER SALES SERVICE
C41: SERVICE FUSO | M41: SERVICE HINO | P41: TOTAL
C42: INTAKE | D42: FREE SERVICE | G42: INTAKE | H42: WARRANTY | I42: INTAKE | L42: CASH | M42: INTAKE | N42: INVOICE | O42: CASH | P42: INTAKE | Q42: TOTAL | R42: Avg
B43: JANUARY | C43: 0 | D43: 0 | G43: 0 | H43: 0 | I43: 2 | L43: 1092.58 | M43: 0 | N43: 0 | O43: 0 | P43: =SUM(C43+G43+I43+M43) -> 2 | Q43: =SUM(D43+H43+L43+N43+O43) -> 1092.58 | R43: =Q43/P43 -> 546.29
B44: FEBRUARY | C44: 0 | D44: 0 | G44: 0 | H44: 0 | I44: 1 | L44: 727.33 | M44: 0 | N44: 0 | O44: 0 | P44: =SUM(C44+G44+I44+M44) -> 1 | Q44: =SUM(D44+H44+L44+N44+O44) -> 727.33 | R44: =Q44/P44 -> 727.33
B45: MARCH | C45: 0 | D45: 0 | G45: 0 | H45: 0 | I45: 1 | L45: 634.33 | M45: 0 | N45: 0 | O45: 0 | P45: =SUM(C45+G45+I45+M45) -> 1 | Q45: =SUM(D45+H45+L45+N45+O45) -> 634.33 | R45: =Q45/P45 -> 634.33
...

Sheet MITSUBISHI MEETING
C2: MITSUBISHI
B3: YA 2024 | C3: ACCIDENT | H3: WINDSCREEN | M3: OTHERS | P3: TOTAL
C4: INTAKE | D4: INS - PARTS | E4: INS - LABOURS | F4: CREDIT | G4: CASH | H4: INTAKE | I4: INS - PARTS | J4: INS - LABOURS | K4: CREDIT | L4: CASH | M4: INTAKE | N4: CASH | O4: CREDIT | P4: INTAKE | Q4: TOTAL | R4: Avg
B5: 45231 | C5: 0 | D5: 0 | E5: 0 | F5: 0 | G5: 0 | H5: 1 | I5: 1084.9 | J5: 228 | K5: 0 | L5: 0 | M5: 1 | N5: 600 | O5: 0 | P5: =SUM(C5+H5+M5) -> 2 | Q5: =SUM(D5+E5+F5+G5+I5+J5+K5+L5+N5+O5) -> 1912.9 | R5: =Q5/P5 -> 956.45
B6: 45261 | C6: 6 | D6: 72705.35 | E6: 21240 | H6: 3 | I6: 5679.72 | J6: 816 | K6: 0 | L6: 0 | M6: 1 | N6: 900 | O6: 0 | P6: =SUM(C6+H6+M6) -> 10 | Q6: =SUM(D6+E6+F6+G6+I6+J6+K6+L6+N6+O6) -> 101341.07 | R6: =Q6/P6 -> 10134.107
B7: 45292 | C7: 7 | D7: 93567.1 | E7: 30384 | G7: 0 | H7: 5 | I7: 9659.41 | J7: 1248 | K7: 0 | L7: 0 | M7: 1 | N7: 1400 | O7: 0 | P7: =SUM(C7+H7+M7) -> 13 | Q7: =SUM(D7+E7+F7+G7+I7+J7+K7+L7+N7+O7) -> 136258.51 | R7: =Q7/P7 -> 10481.424
B8: 45323 | C8: 2 | D8: 52204.13 | E8: 7488 | G8: 0 | H8: 1 | I8: 2237.22 | J8: 240 | K8: 0 | L8: 0 | M8: 1 | N8: 0 | O8: 10870.95 | P8: =SUM(C8+H8+M8) -> 4 | Q8: =SUM(D8+E8+F8+G8+I8+J8+K8+L8+N8+O8) -> 73040.3 | R8: =Q8/P8 -> 18260.075
B9: 45352 | C9: 7 | D9: 82354.95 | E9: 23040 | F9: 8699.63 | G9: 0 | H9: 4 | I9: 6231.13 | J9: 1266 | K9: 0 | L9: 2131.1 | M9: 2 | N9: 1344.1 | O9: 0 | P9: =SUM(C9+H9+M9) -> 13 | Q9: =SUM(D9+E9+F9+G9+I9+J9+K9+L9+N9+O9) -> 125066.91 | R9: =Q9/P9 -> 9620.5315
C10: =SUM(C5:C9) -> 22 | D10: =SUM(D5:D9) -> 300831.53 | E10: =SUM(E5:E9) -> 82152 | F10: =SUM(F5:F9) -> 8699.63 | G10: =SUM(G5:G9) -> 0 | H10: =SUM(H5:H9) -> 14 | I10: =SUM(I5:I9) -> 24892.38 | J10: =SUM(J5:J9) -> 3798 | ... Q10: =SUM(Q5:Q9) -> 437619.69
C15: MITSUBISHI
B16: YA 2025 | C16: ACCIDENT | H16: WINDSCREEN | M16: OTHERS | P16: TOTAL
C17: INTAKE | D17: INS - PARTS | E17: INS - LABOURS | F17: CREDIT | G17: CASH | H17: INTAKE | I17: INS - PARTS | J17: INS - LABOURS | K17: CREDIT | L17: CASH | M17: INTAKE | N17: CASH | O17: CREDIT | P17: INTAKE | Q17: TOTAL | R17: Avg
